Workbook

Sheet GRUPOS
A39: Grupo | B39: Equipos
A40: A | B40: México | C40: Sudáfrica | D40: Corea del Sur | E40: Chequia
A41: B | B41: Canadá | C41: Bosnia y Herzegovina | D41: Qatar | E41: Suiza
A42: C | B42: Brasil | C42: Marruecos | D42: Haití | E42: Escocia
A43: D | B43: Estados Unidos | C43: Paraguay | D43: Australia | E43: Turquía
A44: E | B44: Alemania | C44: Curazao | D44: Costa de Marfil | E44: Ecuador
A45: F | B45: Países Bajos | C45: Japón | D45: Suecia | E45: Túnez
A46: G | B46: Bélgica | C46: Egipto | D46: Irán | E46: Nueva Zelanda
A47: H | B47: España | C47: Cabo Verde | D47: Arabia Saudita | E47: Uruguay
A48: I | B48: Francia | C48: Senegal | D48: Irak | E48: Noruega
A49: J | B49: Argentina | C49: Argelia | D49: Austria | E49: Jordania
A50: K | B50: Portugal | C50: RD Congo | D50: Uzbekistán | E50: Colombia
A51: L | B51: Inglaterra | C51: Croacia | D51: Ghana | E51: Panamá

Sheet Primera Fase
O5: RESULTADOS | AC5: G | AD5: RESULTADOS POR GRUPO
B6: Día | C6: Hora | E6: Estadio | F6: G | G6: Equipos | H6: Resultado | I6: Marcador | K6: Resultado | L6: Equipos | M6: G | O6: G | P6: Equipos | Q6: Partidos | U6: Puntos | V6: Detalle Goles | Z6: Goles | AA6: Lugar | AD6: Posición | AE6: Equipo
B7: 11/06/2026 | C7: 13:00 | D7: México vs Sudáfrica | E7: Estadio Ciudad de México (Ciudad de México) | F7: {=_xlfn.XLOOKUP(TRUE,(GRUPOS!$B$40:$B$51=G7)+(GRUPOS!$C$40:$C$51=G7)+(GRUPOS!$D$40:$D$51=G7)+(GRUPOS!$E$40:$E$51=G7)>0,GRUPOS!$A$40:$A$51)} -> A | G7: =LEFT(D7,FIND(" vs ",D7)-1) -> México | H7: Ganó | I7: 2 | J7: 0 | K7: Perdió | L7: =MID(D7,FIND(" vs ",D7)+4,LEN(D7)) -> Sudáfrica | M7: {=_xlfn.XLOOKUP(TRUE,(GRUPOS!$B$40:$B$51=L7)+(GRUPOS!$C$40:$C$51=L7)+(GRUPOS!$D$40:$D$51=L7)+(GRUPOS!$E$40:$E$51=L7)>0,GRUPOS!$A$40:$A$51)} -> A | O7: A | P7: México | Q7: {=IFERROR(CHOOSE(MATCH(INDEX(_xlfn._xlws.FILTER($H$7:$H$1000,$G$7:$G$1000=P7),1),{"Perdió","Empató","Ganó"},0),0,1,3),"")} -> 3 | R7: {=IFERROR(CHOOSE(MATCH(INDEX(_xlfn._xlws.FILTER($H$7:$H$1000,$G$7:$G$1000=P7),2),{"Perdió","Empató","Ganó"},0),0,1,3),"")} | S7: {=IFERROR(CHOOSE(MATCH(INDEX(_xlfn._xlws.FILTER($K$7:$K$1000,$L$7:$L$1000=P7),1),{"Perdió","Empató","Ganó"},0),0,1,3),"")} | T7: {=IFERROR(CHOOSE(MATCH(INDEX(_xlfn._xlws.FILTER($K$7:$K$1000,$L$7:$L$1000=P7),2),{"Perdió","Empató","Ganó"},0),0,1,3),"")} | U7: =SUM(Q7:S7) -> 3 | V7: {=IFERROR(INDEX(_xlfn._xlws.FILTER($I$7:$I$1000-$J$7:$J$1000,$G$7:$G$1000=P7),1),"")} -> 2 | W7: {=IFERROR(INDEX(_xlfn._xlws.FILTER($I$7:$I$1000-$J$7:$J$1000,$G$7:$G$1000=P7),2),"")} -> 0 | X7: {=IFERROR(INDEX(_xlfn._xlws.FILTER($J$7:$J$1000-$I$7:$I$1000,$L$7:$L$1000=P7),1),"")} -> 0 | Y7: {=IFERROR(INDEX(_xlfn._xlws.FILTER($J$7:$J$1000-$I$7:$I$1000,$L$7:$L$1000=P7),2),"")} | Z7: =SUM(V7:Y7) -> 2 | AA7: {=1+SUMPRODUCT(($U$7:$U$10>U7)+(($U$7:$U$10=U7)*($Z$7:$Z$10>Z7)))} -> 1 | AC7: A | AD7: 1 | AE7: {=IFERROR(_xlfn.TEXTJOIN(" - ",TRUE,_xlfn._xlws.FILTER($P$7:$P$10,$AA$7:$AA$10=1)),"")} -> México
B8: 11/06/2026 | C8: 20:00 | D8: Corea del Sur vs Chequia | E8: Estadio Guadalajara (Guadalajara) | F8: {=_xlfn.XLOOKUP(TRUE,(GRUPOS!$B$40:$B$51=G8)+(GRUPOS!$C$40:$C$51=G8)+(GRUPOS!$D$40:$D$51=G8)+(GRUPOS!$E$40:$E$51=G8)>0,GRUPOS!$A$40:$A$51)} -> A | G8: =LEFT(D8,FIND(" vs ",D8)-1) -> Corea del Sur | H8: Ganó | I8: 2 | J8: 1 | K8: Perdió | L8: =MID(D8,FIND(" vs ",D8)+4,LEN(D8)) -> Chequia | M8: {=_xlfn.XLOOKUP(TRUE,(GRUPOS!$B$40:$B$51=L8)+(GRUPOS!$C$40:$C$51=L8)+(GRUPOS!$D$40:$D$51=L8)+(GRUPOS!$E$40:$E$51=L8)>0,GRUPOS!$A$40:$A$51)} -> A | O8: A | P8: Sudáfrica | Q8: {=IFERROR(CHOOSE(MATCH(INDEX(_xlfn._xlws.FILTER($H$7:$H$1000,$G$7:$G$1000=P8),1),{"Perdió","Empató","Ganó"},0),0,1,3),"")} | R8: {=IFERROR(CHOOSE(MATCH(INDEX(_xlfn._xlws.FILTER($H$7:$H$1000,$G$7:$G$1000=P8),2),{"Perdió","Empató","Ganó"},0),0,1,3),"")} | S8: {=IFERROR(CHOOSE(MATCH(INDEX(_xlfn._xlws.FILTER($K$7:$K$1000,$L$7:$L$1000=P8),1),{"Perdió","Empató","Ganó"},0),0,1,3),"")} -> 0 | T8: {=IFERROR(CHOOSE(MATCH(INDEX(_xlfn._xlws.FILTER($K$7:$K$1000,$L$7:$L$1000=P8),2),{"Perdió","Empató","Ganó"},0),0,1,3),"")} | U8: =SUM(Q8:S8) -> 0 | V8: {=IFERROR(INDEX(_xlfn._xlws.FILTER($I$7:$I$1000-$J$7:$J$1000,$G$7:$G$1000=P8),1),"")} -> 0 | W8: {=IFERROR(INDEX(_xlfn._xlws.FILTER($I$7:$I$1000-$J$7:$J$1000,$G$7:$G$1000=P8),2),"")} | X8: {=IFERROR(INDEX(_xlfn._xlws.FILTER($J$7:$J$1000-$I$7:$I$1000,$L$7:$L$1000=P8),1),"")} -> -2 | Y8: {=IFERROR(INDEX(_xlfn._xlws.FILTER($J$7:$J$1000-$I$7:$I$1000,$L$7:$L$1000=P8),2),"")} -> 0 | Z8: =SUM(V8:Y8) -> -2 | AA8: {=1+SUMPRODUCT(($U$7:$U$10>U8)+(($U$7:$U$10=U8)*($Z$7:$Z$10>Z8)))} -> 4 | AC8: A | AD8: 2 | AE8: {=IFERROR(_xlfn.TEXTJOIN(" - ",TRUE,_xlfn._xlws.FILTER($P$7:$P$10,$AA$7:$AA$10=2)),"")} -> Corea del Sur
B9: 12/06/2026 | C9: 13:00 | D9: Canadá vs Bosnia y Herzegovina | E9: Estadio de Toronto (Toronto) | F9: {=_xlfn.XLOOKUP(TRUE,(GRUPOS!$B$40:$B$51=G9)+(GRUPOS!$C$40:$C$51=G9)+(GRUPOS!$D$40:$D$51=G9)+(GRUPOS!$E$40:$E$51=G9)>0,GRUPOS!$A$40:$A$51)} -> B | G9: =LEFT(D9,FIND(" vs ",D9)-1) -> Canadá | H9: Empató | I9: 1 | J9: 1 | K9: Empató | L9: =MID(D9,FIND(" vs ",D9)+4,LEN(D9)) -> Bosnia y Herzegovina | M9: {=_xlfn.XLOOKUP(TRUE,(GRUPOS!$B$40:$B$51=L9)+(GRUPOS!$C$40:$C$51=L9)+(GRUPOS!$D$40:$D$51=L9)+(GRUPOS!$E$40:$E$51=L9)>0,GRUPOS!$A$40:$A$51)} -> B | O9: A | P9: Corea del Sur | Q9: {=IFERROR(CHOOSE(MATCH(INDEX(_xlfn._xlws.FILTER($H$7:$H$1000,$G$7:$G$1000=P9),1),{"Perdió","Empató","Ganó"},0),0,1,3),"")} -> 3 | R9: {=IFERROR(CHOOSE(MATCH(INDEX(_xlfn._xlws.FILTER($H$7:$H$1000,$G$7:$G$1000=P9),2),{"Perdió","Empató","Ganó"},0),0,1,3),"")} | S9: {=IFERROR(CHOOSE(MATCH(INDEX(_xlfn._xlws.FILTER($K$7:$K$1000,$L$7:$L$1000=P9),1),{"Perdió","Empató","Ganó"},0),0,1,3),"")} | T9: {=IFERROR(CHOOSE(MATCH(INDEX(_xlfn._xlws.FILTER($K$7:$K$1000,$L$7:$L$1000=P9),2),{"Perdió","Empató","Ganó"},0),0,1,3),"")} | U9: =SUM(Q9:S9) -> 3 | V9: {=IFERROR(INDEX(_xlfn._xlws.FILTER($I$7:$I$1000-$J$7:$J$1000,$G$7:$G$1000=P9),1),"")} -> 1 | W9: {=IFERROR(INDEX(_xlfn._xlws.FILTER($I$7:$I$1000-$J$7:$J$1000,$G$7:$G$1000=P9),2),"")} | X9: {=IFERROR(INDEX(_xlfn._xlws.FILTER($J$7:$J$1000-$I$7:$I$1000,$L$7:$L$1000=P9),1),"")} -> 0 | Y9: {=IFERROR(INDEX(_xlfn._xlws.FILTER($J$7:$J$1000-$I$7:$I$1000,$L$7:$L$1000=P9),2),"")} -> 0 | Z9: =SUM(V9:Y9) -> 1 | AA9: {=1+SUMPRODUCT(($U$7:$U$10>U9)+(($U$7:$U$10=U9)*($Z$7:$Z$10>Z9)))} -> 2 | AC9: A | AD9: 3 | AE9: {=IFERROR(_xlfn.TEXTJOIN(" - ",TRUE,_xlfn._xlws.FILTER($P$7:$P$10,$AA$7:$AA$10=3)),"")} -> Chequia
B10: 12/06/2026 | C10: 19:00 | D10: Estados Unidos vs Paraguay | E10: Estadio Los Ángeles (Los Ángeles) | F10: {=_xlfn.XLOOKUP(TRUE,(GRUPOS!$B$40:$B$51=G10)+(GRUPOS!$C$40:$C$51=G10)+(GRUPOS!$D$40:$D$51=G10)+(GRUPOS!$E$40:$E$51=G10)>0,GRUPOS!$A$40:$A$51)} -> D | G10: =LEFT(D10,FIND(" vs ",D10)-1) -> Estados Unidos | H10: Ganó | I10: 4 | J10: 1 | K10: Perdió | L10: =MID(D10,FIND(" vs ",D10)+4,LEN(D10)) -> Paraguay | M10: {=_xlfn.XLOOKUP(TRUE,(GRUPOS!$B$40:$B$51=L10)+(GRUPOS!$C$40:$C$51=L10)+(GRUPOS!$D$40:$D$51=L10)+(GRUPOS!$E$40:$E$51=L10)>0,GRUPOS!$A$40:$A$51)} -> D | O10: A | P10: Chequia | Q10: {=IFERROR(CHOOSE(MATCH(INDEX(_xlfn._xlws.FILTER($H$7:$H$1000,$G$7:$G$1000=P10),1),{"Perdió","Empató","Ganó"},0),0,1,3),"")} | R10: {=IFERROR(CHOOSE(MATCH(INDEX(_xlfn._xlws.FILTER($H$7:$H$1000,$G$7:$G$1000=P10),2),{"Perdió","Empató","Ganó"},0),0,1,3),"")} | S10: {=IFERROR(CHOOSE(MATCH(INDEX(_xlfn._xlws.FILTER($K$7:$K$1000,$L$7:$L$1000=P10),1),{"Perdió","Empató","Ganó"},0),0,1,3),"")} -> 0 | T10: {=IFERROR(CHOOSE(MATCH(INDEX(_xlfn._xlws.FILTER($K$7:$K$1000,$L$7:$L$1000=P10),2),{"Perdió","Empató","Ganó"},0),0,1,3),"")} | U10: =SUM(Q10:S10) -> 0 | V10: {=IFERROR(INDEX(_xlfn._xlws.FILTER($I$7:$I$1000-$J$7:$J$1000,$G$7:$G$1000=P10),1),"")} -> 0 | W10: {=IFERROR(INDEX(_xlfn._xlws.FILTER($I$7:$I$1000-$J$7:$J$1000,$G$7:$G$1000=P10),2),"")} -> 0 | X10: {=IFERROR(INDEX(_xlfn._xlws.FILTER($J$7:$J$1000-$I$7:$I$1000,$L$7:$L$1000=P10),1),"")} -> -1 | Y10: {=IFERROR(INDEX(_xlfn._xlws.FILTER($J$7:$J$1000-$I$7:$I$1000,$L$7:$L$1000=P10),2),"")} | Z10: =SUM(V10:Y10) -> -1 | AA10: {=1+SUMPRODUCT(($U$7:$U$10>U10)+(($U$7:$U$10=U10)*($Z$7:$Z$10>Z10)))} -> 3 | AC10: A | AD10: 4 | AE10: {=IFERROR(_xlfn.TEXTJOIN(" - ",TRUE,_xlfn._xlws.FILTER($P$7:$P$10,$AA$7:$AA$10=4)),"")} -> Sudáfrica
B11: 13/06/2026 | C11: 13:00 | D11: Qatar vs Suiza | E11: Estadio de la Bahía de San Francisco | F11: {=_xlfn.XLOOKUP(TRUE,(GRUPOS!$B$40:$B$51=G11)+(GRUPOS!$C$40:$C$51=G11)+(GRUPOS!$D$40:$D$51=G11)+(GRUPOS!$E$40:$E$51=G11)>0,GRUPOS!$A$40:$A$51)} -> B | G11: =LEFT(D11,FIND(" vs ",D11)-1) -> Qatar | H11: Empató | I11: 1 | J11: 1 | K11: Empató | L11: =MID(D11,FIND(" vs ",D11)+4,LEN(D11)) -> Suiza | M11: {=_xlfn.XLOOKUP(TRUE,(GRUPOS!$B$40:$B$51=L11)+(GRUPOS!$C$40:$C$51=L11)+(GRUPOS!$D$40:$D$51=L11)+(GRUPOS!$E$40:$E$51=L11)>0,GRUPOS!$A$40:$A$51)} -> B | O11: B | P11: Canadá | Q11: {=IFERROR(CHOOSE(MATCH(INDEX(_xlfn._xlws.FILTER($H$7:$H$1000,$G$7:$G$1000=P11),1),{"Perdió","Empató","Ganó"},0),0,1,3),"")} -> 1 | R11: {=IFERROR(CHOOSE(MATCH(INDEX(_xlfn._xlws.FILTER($H$7:$H$1000,$G$7:$G$1000=P11),2),{"Perdió","Empató","Ganó"},0),0,1,3),"")} | S11: {=IFERROR(CHOOSE(MATCH(INDEX(_xlfn._xlws.FILTER($K$7:$K$1000,$L$7:$L$1000=P11),1),{"Perdió","Empató","Ganó"},0),0,1,3),"")} | T11: {=IFERROR(CHOOSE(MATCH(INDEX(_xlfn._xlws.FILTER($K$7:$K$1000,$L$7:$L$1000=P11),2),{"Perdió","Empató","Ganó"},0),0,1,3),"")} | U11: =SUM(Q11:S11) -> 1 | V11: {=IFERROR(INDEX(_xlfn._xlws.FILTER($I$7:$I$1000-$J$7:$J$1000,$G$7:$G$1000=P11),1),"")} -> 0 | W11: {=IFERROR(INDEX(_xlfn._xlws.FILTER($I$7:$I$1000-$J$7:$J$1000,$G$7:$G$1000=P11),2),"")} -> 0 | X11: {=IFERROR(INDEX(_xlfn._xlws.FILTER($J$7:$J$1000-$I$7:$I$1000,$L$7:$L$1000=P11),1),"")} -> 0 | Y11: {=IFERROR(INDEX(_xlfn._xlws.FILTER($J$7:$J$1000-$I$7:$I$1000,$L$7:$L$1000=P11),2),"")} | Z11: =SUM(V11:Y11) -> 0 | AA11: {=1+SUMPRODUCT(($U$11:$U$14>U11)+(($U$11:$U$14=U11)*($Z$11:$Z$14>Z11)))} -> 1 | AC11: B | AD11: 1 | AE11: {=IFERROR(_xlfn.TEXTJOIN(" - ",TRUE,_xlfn._xlws.FILTER($P$11:$P$14,$AA$11:$AA$14=1)),"")} -> Canadá - Bosnia y Herzegovina - Qatar - Suiza
B12: 13/06/2026 | C12: 16:00 | D12: Brasil vs Marruecos | E12: Estadio Nueva York/Nueva Jersey | F12: {=_xlfn.XLOOKUP(TRUE,(GRUPOS!$B$40:$B$51=G12)+(GRUPOS!$C$40:$C$51=G12)+(GRUPOS!$D$40:$D$51=G12)+(GRUPOS!$E$40:$E$51=G12)>0,GRUPOS!$A$40:$A$51)} -> C | G12: =LEFT(D12,FIND(" vs ",D12)-1) -> Brasil | H12: Empató | I12: 1 | J12: 1 | K12: Empató | L12: =MID(D12,FIND(" vs ",D12)+4,LEN(D12)) -> Marruecos | M12: {=_xlfn.XLOOKUP(TRUE,(GRUPOS!$B$40:$B$51=L12)+(GRUPOS!$C$40:$C$51=L12)+(GRUPOS!$D$40:$D$51=L12)+(GRUPOS!$E$40:$E$51=L12)>0,GRUPOS!$A$40:$A$51)} -> C | O12: B | P12: Bosnia y Herzegovina | Q12: {=IFERROR(CHOOSE(MATCH(INDEX(_xlfn._xlws.FILTER($H$7:$H$1000,$G$7:$G$1000=P12),1),{"Perdió","Empató","Ganó"},0),0,1,3),"")} | R12: {=IFERROR(CHOOSE(MATCH(INDEX(_xlfn._xlws.FILTER($H$7:$H$1000,$G$7:$G$1000=P12),2),{"Perdió","Empató","Ganó"},0),0,1,3),"")} | S12: {=IFERROR(CHOOSE(MATCH(INDEX(_xlfn._xlws.FILTER($K$7:$K$1000,$L$7:$L$1000=P12),1),{"Perdió","Empató","Ganó"},0),0,1,3),"")} -> 1 | T12: {=IFERROR(CHOOSE(MATCH(INDEX(_xlfn._xlws.FILTER($K$7:$K$1000,$L$7:$L$1000=P12),2),{"Perdió","Empató","Ganó"},0),0,1,3),"")} | U12: =SUM(Q12:S12) -> 1 | V12: {=IFERROR(INDEX(_xlfn._xlws.FILTER($I$7:$I$1000-$J$7:$J$1000,$G$7:$G$1000=P12),1),"")} -> 0 | W12: {=IFERROR(INDEX(_xlfn._xlws.FILTER($I$7:$I$1000-$J$7:$J$1000,$G$7:$G$1000=P12),2),"")} | X12: {=IFERROR(INDEX(_xlfn._xlws.FILTER($J$7:$J$1000-$I$7:$I$1000,$L$7:$L$1000=P12),1),"")} -> 0 | Y12: {=IFERROR(INDEX(_xlfn._xlws.FILTER($J$7:$J$1000-$I$7:$I$1000,$L$7:$L$1000=P12),2),"")} -> 0 | Z12: =SUM(V12:Y12) -> 0 | AA12: {=1+SUMPRODUCT(($U$11:$U$14>U12)+(($U$11:$U$14=U12)*($Z$11:$Z$14>Z12)))} -> 1 | AC12: B | AD12: 2 | AE12: {=IFERROR(_xlfn.TEXTJOIN(" - ",TRUE,_xlfn._xlws.FILTER($P$11:$P$14,$AA$11:$AA$14=2)),"")}
B13: 13/06/2026 | C13: 19:00 | D13: Haití vs Escocia | E13: Estadio Boston (Boston) | F13: {=_xlfn.XLOOKUP(TRUE,(GRUPOS!$B$40:$B$51=G13)+(GRUPOS!$C$40:$C$51=G13)+(GRUPOS!$D$40:$D$51=G13)+(GRUPOS!$E$40:$E$51=G13)>0,GRUPOS!$A$40:$A$51)} -> C | G13: =LEFT(D13,FIND(" vs ",D13)-1) -> Haití | H13: Perdió | I13: 0 | J13: 1 | K13: Ganó | L13: =MID(D13,FIND(" vs ",D13)+4,LEN(D13)) -> Escocia | M13: {=_xlfn.XLOOKUP(TRUE,(GRUPOS!$B$40:$B$51=L13)+(GRUPOS!$C$40:$C$51=L13)+(GRUPOS!$D$40:$D$51=L13)+(GRUPOS!$E$40:$E$51=L13)>0,GRUPOS!$A$40:$A$51)} -> C | O13: B | P13: Qatar | Q13: {=IFERROR(CHOOSE(MATCH(INDEX(_xlfn._xlws.FILTER($H$7:$H$1000,$G$7:$G$1000=P13),1),{"Perdió","Empató","Ganó"},0),0,1,3),"")} -> 1 | R13: {=IFERROR(CHOOSE(MATCH(INDEX(_xlfn._xlws.FILTER($H$7:$H$1000,$G$7:$G$1000=P13),2),{"Perdió","Empató","Ganó"},0),0,1,3),"")} | S13: {=IFERROR(CHOOSE(MATCH(INDEX(_xlfn._xlws.FILTER($K$7:$K$1000,$L$7:$L$1000=P13),1),{"Perdió","Empató","Ganó"},0),0,1,3),"")} | T13: {=IFERROR(CHOOSE(MATCH(INDEX(_xlfn._xlws.FILTER($K$7:$K$1000,$L$7:$L$1000=P13),2),{"Perdió","Empató","Ganó"},0),0,1,3),"")} | U13: =SUM(Q13:S13) -> 1 | V13: {=IFERROR(INDEX(_xlfn._xlws.FILTER($I$7:$I$1000-$J$7:$J$1000,$G$7:$G$1000=P13),1),"")} -> 0 | W13: {=IFERROR(INDEX(_xlfn._xlws.FILTER($I$7:$I$1000-$J$7:$J$1000,$G$7:$G$1000=P13),2),"")} | X13: {=IFERROR(INDEX(_xlfn._xlws.FILTER($J$7:$J$1000-$I$7:$I$1000,$L$7:$L$1000=P13),1),"")} -> 0 | Y13: {=IFERROR(INDEX(_xlfn._xlws.FILTER($J$7:$J$1000-$I$7:$I$1000,$L$7:$L$1000=P13),2),"")} -> 0 | Z13: =SUM(V13:Y13) -> 0 | AA13: {=1+SUMPRODUCT(($U$11:$U$14>U13)+(($U$11:$U$14=U13)*($Z$11:$Z$14>Z13)))} -> 1 | AC13: B | AD13: 3 | AE13: {=IFERROR(_xlfn.TEXTJOIN(" - ",TRUE,_xlfn._xlws.FILTER($P$11:$P$14,$AA$11:$AA$14=3)),"")}
B14: 13/06/2026 | C14: 22:00 | D14: Australia vs Turquía | E14: Estadio BC Place Vancouver | F14: {=_xlfn.XLOOKUP(TRUE,(GRUPOS!$B$40:$B$51=G14)+(GRUPOS!$C$40:$C$51=G14)+(GRUPOS!$D$40:$D$51=G14)+(GRUPOS!$E$40:$E$51=G14)>0,GRUPOS!$A$40:$A$51)} -> D | G14: =LEFT(D14,FIND(" vs ",D14)-1) -> Australia | H14: Ganó | I14: 2 | J14: 0 | K14: Perdió | L14: =MID(D14,FIND(" vs ",D14)+4,LEN(D14)) -> Turquía | M14: {=_xlfn.XLOOKUP(TRUE,(GRUPOS!$B$40:$B$51=L14)+(GRUPOS!$C$40:$C$51=L14)+(GRUPOS!$D$40:$D$51=L14)+(GRUPOS!$E$40:$E$51=L14)>0,GRUPOS!$A$40:$A$51)} -> D | O14: B | P14: Suiza | Q14: {=IFERROR(CHOOSE(MATCH(INDEX(_xlfn._xlws.FILTER($H$7:$H$1000,$G$7:$G$1000=P14),1),{"Perdió","Empató","Ganó"},0),0,1,3),"")} | R14: {=IFERROR(CHOOSE(MATCH(INDEX(_xlfn._xlws.FILTER($H$7:$H$1000,$G$7:$G$1000=P14),2),{"Perdió","Empató","Ganó"},0),0,1,3),"")} | S14: {=IFERROR(CHOOSE(MATCH(INDEX(_xlfn._xlws.FILTER($K$7:$K$1000,$L$7:$L$1000=P14),1),{"Perdió","Empató","Ganó"},0),0,1,3),"")} -> 1 | T14: {=IFERROR(CHOOSE(MATCH(INDEX(_xlfn._xlws.FILTER($K$7:$K$1000,$L$7:$L$1000=P14),2),{"Perdió","Empató","Ganó"},0),0,1,3),"")} | U14: =SUM(Q14:S14) -> 1 | V14: {=IFERROR(INDEX(_xlfn._xlws.FILTER($I$7:$I$1000-$J$7:$J$1000,$G$7:$G$1000=P14),1),"")} -> 0 | W14: {=IFERROR(INDEX(_xlfn._xlws.FILTER($I$7:$I$1000-$J$7:$J$1000,$G$7:$G$1000=P14),2),"")} -> 0 | X14: {=IFERROR(INDEX(_xlfn._xlws.FILTER($J$7:$J$1000-$I$7:$I$1000,$L$7:$L$1000=P14),1),"")} -> 0 | Y14: {=IFERROR(INDEX(_xlfn._xlws.FILTER($J$7:$J$1000-$I$7:$I$1000,$L$7:$L$1000=P14),2),"")} | Z14: =SUM(V14:Y14) -> 0 | AA14: {=1+SUMPRODUCT(($U$11:$U$14>U14)+(($U$11:$U$14=U14)*($Z$11:$Z$14>Z14)))} -> 1 | AC14: B | AD14: 4 | AE14: {=IFERROR(_xlfn.TEXTJOIN(" - ",TRUE,_xlfn._xlws.FILTER($P$11:$P$14,$AA$11:$AA$14=4)),"")}
B15: 14/06/2026 | C15: 11:00 | D15: Alemania vs Curazao | E15: Estadio Houston (Houston) | F15: {=_xlfn.XLOOKUP(TRUE,(GRUPOS!$B$40:$B$51=G15)+(GRUPOS!$C$40:$C$51=G15)+(GRUPOS!$D$40:$D$51=G15)+(GRUPOS!$E$40:$E$51=G15)>0,GRUPOS!$A$40:$A$51)} -> E | G15: =LEFT(D15,FIND(" vs ",D15)-1) -> Alemania | H15: Ganó | I15: 7 | J15: 1 | K15: Perdió | L15: =MID(D15,FIND(" vs ",D15)+4,LEN(D15)) -> Curazao | M15: {=_xlfn.XLOOKUP(TRUE,(GRUPOS!$B$40:$B$51=L15)+(GRUPOS!$C$40:$C$51=L15)+(GRUPOS!$D$40:$D$51=L15)+(GRUPOS!$E$40:$E$51=L15)>0,GRUPOS!$A$40:$A$51)} -> E | O15: C | P15: Brasil | Q15: {=IFERROR(CHOOSE(MATCH(INDEX(_xlfn._xlws.FILTER($H$7:$H$1000,$G$7:$G$1000=P15),1),{"Perdió","Empató","Ganó"},0),0,1,3),"")} -> 1 | R15: {=IFERROR(CHOOSE(MATCH(INDEX(_xlfn._xlws.FILTER($H$7:$H$1000,$G$7:$G$1000=P15),2),{"Perdió","Empató","Ganó"},0),0,1,3),"")} | S15: {=IFERROR(CHOOSE(MATCH(INDEX(_xlfn._xlws.FILTER($K$7:$K$1000,$L$7:$L$1000=P15),1),{"Perdió","Empató","Ganó"},0),0,1,3),"")} | T15: {=IFERROR(CHOOSE(MATCH(INDEX(_xlfn._xlws.FILTER($K$7:$K$1000,$L$7:$L$1000=P15),2),{"Perdió","Empató","Ganó"},0),0,1,3),"")} | U15: =SUM(Q15:S15) -> 1 | V15: {=IFERROR(INDEX(_xlfn._xlws.FILTER($I$7:$I$1000-$J$7:$J$1000,$G$7:$G$1000=P15),1),"")} -> 0 | W15: {=IFERROR(INDEX(_xlfn._xlws.FILTER($I$7:$I$1000-$J$7:$J$1000,$G$7:$G$1000=P15),2),"")} -> 0 | X15: {=IFERROR(INDEX(_xlfn._xlws.FILTER($J$7:$J$1000-$I$7:$I$1000,$L$7:$L$1000=P15),1),"")} -> 0 | Y15: {=IFERROR(INDEX(_xlfn._xlws.FILTER($J$7:$J$1000-$I$7:$I$1000,$L$7:$L$1000=P15),2),"")} | Z15: =SUM(V15:Y15) -> 0 | AA15: {=1+SUMPRODUCT(($U$15:$U$18>U15)+(($U$15:$U$18=U15)*($Z$15:$Z$18>Z15)))} -> 2 | AC15: C | AD15: 1 | AE15: {=IFERROR(_xlfn.TEXTJOIN(" - ",TRUE,_xlfn._xlws.FILTER($P$15:$P$18,$AA$15:$AA$18=1)),"")} -> Escocia
B16: 14/06/2026 | C16: 14:00 | D16: Países Bajos vs Japón | E16: Estadio Dallas (Dallas) | F16: {=_xlfn.XLOOKUP(TRUE,(GRUPOS!$B$40:$B$51=G16)+(GRUPOS!$C$40:$C$51=G16)+(GRUPOS!$D$40:$D$51=G16)+(GRUPOS!$E$40:$E$51=G16)>0,GRUPOS!$A$40:$A$51)} -> F | G16: =LEFT(D16,FIND(" vs ",D16)-1) -> Países Bajos | H16: Empató | I16: 2 | J16: 2 | K16: Empató | L16: =MID(D16,FIND(" vs ",D16)+4,LEN(D16)) -> Japón | M16: {=_xlfn.XLOOKUP(TRUE,(GRUPOS!$B$40:$B$51=L16)+(GRUPOS!$C$40:$C$51=L16)+(GRUPOS!$D$40:$D$51=L16)+(GRUPOS!$E$40:$E$51=L16)>0,GRUPOS!$A$40:$A$51)} -> F | O16: C | P16: Marruecos | Q16: {=IFERROR(CHOOSE(MATCH(INDEX(_xlfn._xlws.FILTER($H$7:$H$1000,$G$7:$G$1000=P16),1),{"Perdió","Empató","Ganó"},0),0,1,3),"")} | R16: {=IFERROR(CHOOSE(MATCH(INDEX(_xlfn._xlws.FILTER($H$7:$H$1000,$G$7:$G$1000=P16),2),{"Perdió","Empató","Ganó"},0),0,1,3),"")} | S16: {=IFERROR(CHOOSE(MATCH(INDEX(_xlfn._xlws.FILTER($K$7:$K$1000,$L$7:$L$1000=P16),1),{"Perdió","Empató","Ganó"},0),0,1,3),"")} -> 1 | T16: {=IFERROR(CHOOSE(MATCH(INDEX(_xlfn._xlws.FILTER($K$7:$K$1000,$L$7:$L$1000=P16),2),{"Perdió","Empató","Ganó"},0),0,1,3),"")} | U16: =SUM(Q16:S16) -> 1 | V16: {=IFERROR(INDEX(_xlfn._xlws.FILTER($I$7:$I$1000-$J$7:$J$1000,$G$7:$G$1000=P16),1),"")} -> 0 | W16: {=IFERROR(INDEX(_xlfn._xlws.FILTER($I$7:$I$1000-$J$7:$J$1000,$G$7:$G$1000=P16),2),"")} | X16: {=IFERROR(INDEX(_xlfn._xlws.FILTER($J$7:$J$1000-$I$7:$I$1000,$L$7:$L$1000=P16),1),"")} -> 0 | Y16: {=IFERROR(INDEX(_xlfn._xlws.FILTER($J$7:$J$1000-$I$7:$I$1000,$L$7:$L$1000=P16),2),"")} -> 0 | Z16: =SUM(V16:Y16) -> 0 | AA16: {=1+SUMPRODUCT(($U$15:$U$18>U16)+(($U$15:$U$18=U16)*($Z$15:$Z$18>Z16)))} -> 2 | AC16: C | AD16: 2 | AE16: {=IFERROR(_xlfn.TEXTJOIN(" - ",TRUE,_xlfn._xlws.FILTER($P$15:$P$18,$AA$15:$AA$18=2)),"")} -> Brasil - Marruecos
B17: 14/06/2026 | C17: 17:00 | D17: Costa de Marfil vs Ecuador | E17: Estadio Filadelfia (Filadelfia) | F17: {=_xlfn.XLOOKUP(TRUE,(GRUPOS!$B$40:$B$51=G17)+(GRUPOS!$C$40:$C$51=G17)+(GRUPOS!$D$40:$D$51=G17)+(GRUPOS!$E$40:$E$51=G17)>0,GRUPOS!$A$40:$A$51)} -> E | G17: =LEFT(D17,FIND(" vs ",D17)-1) -> Costa de Marfil | H17: Ganó | I17: 1 | J17: 0 | K17: Perdió | L17: =MID(D17,FIND(" vs ",D17)+4,LEN(D17)) -> Ecuador | M17: {=_xlfn.XLOOKUP(TRUE,(GRUPOS!$B$40:$B$51=L17)+(GRUPOS!$C$40:$C$51=L17)+(GRUPOS!$D$40:$D$51=L17)+(GRUPOS!$E$40:$E$51=L17)>0,GRUPOS!$A$40:$A$51)} -> E | O17: C | P17: Haití | Q17: {=IFERROR(CHOOSE(MATCH(INDEX(_xlfn._xlws.FILTER($H$7:$H$1000,$G$7:$G$1000=P17),1),{"Perdió","Empató","Ganó"},0),0,1,3),"")} -> 0 | R17: {=IFERROR(CHOOSE(MATCH(INDEX(_xlfn._xlws.FILTER($H$7:$H$1000,$G$7:$G$1000=P17),2),{"Perdió","Empató","Ganó"},0),0,1,3),"")} | S17: {=IFERROR(CHOOSE(MATCH(INDEX(_xlfn._xlws.FILTER($K$7:$K$1000,$L$7:$L$1000=P17),1),{"Perdió","Empató","Ganó"},0),0,1,3),"")} | T17: {=IFERROR(CHOOSE(MATCH(INDEX(_xlfn._xlws.FILTER($K$7:$K$1000,$L$7:$L$1000=P17),2),{"Perdió","Empató","Ganó"},0),0,1,3),"")} | U17: =SUM(Q17:S17) -> 0 | V17: {=IFERROR(INDEX(_xlfn._xlws.FILTER($I$7:$I$1000-$J$7:$J$1000,$G$7:$G$1000=P17),1),"")} -> -1 | W17: {=IFERROR(INDEX(_xlfn._xlws.FILTER($I$7:$I$1000-$J$7:$J$1000,$G$7:$G$1000=P17),2),"")} | X17: {=IFERROR(INDEX(_xlfn._xlws.FILTER($J$7:$J$1000-$I$7:$I$1000,$L$7:$L$1000=P17),1),"")} -> 0 | Y17: {=IFERROR(INDEX(_xlfn._xlws.FILTER($J$7:$J$1000-$I$7:$I$1000,$L$7:$L$1000=P17),2),"")} -> 0 | Z17: =SUM(V17:Y17) -> -1 | AA17: {=1+SUMPRODUCT(($U$15:$U$18>U17)+(($U$15:$U$18=U17)*($Z$15:$Z$18>Z17)))} -> 4 | AC17: C | AD17: 3 | AE17: {=IFERROR(_xlfn.TEXTJOIN(" - ",TRUE,_xlfn._xlws.FILTER($P$15:$P$18,$AA$15:$AA$18=3)),"")}
B18: 14/06/2026 | C18: 20:00 | D18: Suecia vs Túnez | E18: Estadio Monterrey (Monterrey) | F18: {=_xlfn.XLOOKUP(TRUE,(GRUPOS!$B$40:$B$51=G18)+(GRUPOS!$C$40:$C$51=G18)+(GRUPOS!$D$40:$D$51=G18)+(GRUPOS!$E$40:$E$51=G18)>0,GRUPOS!$A$40:$A$51)} -> F | G18: =LEFT(D18,FIND(" vs ",D18)-1) -> Suecia | L18: =MID(D18,FIND(" vs ",D18)+4,LEN(D18)) -> Túnez | M18: {=_xlfn.XLOOKUP(TRUE,(GRUPOS!$B$40:$B$51=L18)+(GRUPOS!$C$40:$C$51=L18)+(GRUPOS!$D$40:$D$51=L18)+(GRUPOS!$E$40:$E$51=L18)>0,GRUPOS!$A$40:$A$51)} -> F | O18: C | P18: Escocia | Q18: {=IFERROR(CHOOSE(MATCH(INDEX(_xlfn._xlws.FILTER($H$7:$H$1000,$G$7:$G$1000=P18),1),{"Perdió","Empató","Ganó"},0),0,1,3),"")} | R18: {=IFERROR(CHOOSE(MATCH(INDEX(_xlfn._xlws.FILTER($H$7:$H$1000,$G$7:$G$1000=P18),2),{"Perdió","Empató","Ganó"},0),0,1,3),"")} | S18: {=IFERROR(CHOOSE(MATCH(INDEX(_xlfn._xlws.FILTER($K$7:$K$1000,$L$7:$L$1000=P18),1),{"Perdió","Empató","Ganó"},0),0,1,3),"")} -> 3 | T18: {=IFERROR(CHOOSE(MATCH(INDEX(_xlfn._xlws.FILTER($K$7:$K$1000,$L$7:$L$1000=P18),2),{"Perdió","Empató","Ganó"},0),0,1,3),"")} | U18: =SUM(Q18:S18) -> 3 | V18: {=IFERROR(INDEX(_xlfn._xlws.FILTER($I$7:$I$1000-$J$7:$J$1000,$G$7:$G$1000=P18),1),"")} -> 0 | W18: {=IFERROR(INDEX(_xlfn._xlws.FILTER($I$7:$I$1000-$J$7:$J$1000,$G$7:$G$1000=P18),2),"")} -> 0 | X18: {=IFERROR(INDEX(_xlfn._xlws.FILTER($J$7:$J$1000-$I$7:$I$1000,$L$7:$L$1000=P18),1),"")} -> 1 | Y18: {=IFERROR(INDEX(_xlfn._xlws.FILTER($J$7:$J$1000-$I$7:$I$1000,$L$7:$L$1000=P18),2),"")} | Z18: =SUM(V18:Y18) -> 1 | AA18: {=1+SUMPRODUCT(($U$15:$U$18>U18)+(($U$15:$U$18=U18)*($Z$15:$Z$18>Z18)))} -> 1 | AC18: C | AD18: 4 | AE18: {=IFERROR(_xlfn.TEXTJOIN(" - ",TRUE,_xlfn._xlws.FILTER($P$15:$P$18,$AA$15:$AA$18=4)),"")} -> Haití
B19: 15/06/2026 | C19: 10:00 | D19: España vs Cabo Verde | E19: Estadio Atlanta (Atlanta) | F19: {=_xlfn.XLOOKUP(TRUE,(GRUPOS!$B$40:$B$51=G19)+(GRUPOS!$C$40:$C$51=G19)+(GRUPOS!$D$40:$D$51=G19)+(GRUPOS!$E$40:$E$51=G19)>0,GRUPOS!$A$40:$A$51)} -> H | G19: =LEFT(D19,FIND(" vs ",D19)-1) -> España | L19: =MID(D19,FIND(" vs ",D19)+4,LEN(D19)) -> Cabo Verde | M19: {=_xlfn.XLOOKUP(TRUE,(GRUPOS!$B$40:$B$51=L19)+(GRUPOS!$C$40:$C$51=L19)+(GRUPOS!$D$40:$D$51=L19)+(GRUPOS!$E$40:$E$51=L19)>0,GRUPOS!$A$40:$A$51)} -> H | O19: D | P19: Estados Unidos | Q19: {=IFERROR(CHOOSE(MATCH(INDEX(_xlfn._xlws.FILTER($H$7:$H$1000,$G$7:$G$1000=P19),1),{"Perdió","Empató","Ganó"},0),0,1,3),"")} -> 3 | R19: {=IFERROR(CHOOSE(MATCH(INDEX(_xlfn._xlws.FILTER($H$7:$H$1000,$G$7:$G$1000=P19),2),{"Perdió","Empató","Ganó"},0),0,1,3),"")} | S19: {=IFERROR(CHOOSE(MATCH(INDEX(_xlfn._xlws.FILTER($K$7:$K$1000,$L$7:$L$1000=P19),1),{"Perdió","Empató","Ganó"},0),0,1,3),"")} | T19: {=IFERROR(CHOOSE(MATCH(INDEX(_xlfn._xlws.FILTER($K$7:$K$1000,$L$7:$L$1000=P19),2),{"Perdió","Empató","Ganó"},0),0,1,3),"")} | U19: =SUM(Q19:S19) -> 3 | V19: {=IFERROR(INDEX(_xlfn._xlws.FILTER($I$7:$I$1000-$J$7:$J$1000,$G$7:$G$1000=P19),1),"")} -> 3 | W19: {=IFERROR(INDEX(_xlfn._xlws.FILTER($I$7:$I$1000-$J$7:$J$1000,$G$7:$G$1000=P19),2),"")} -> 0 | X19: {=IFERROR(INDEX(_xlfn._xlws.FILTER($J$7:$J$1000-$I$7:$I$1000,$L$7:$L$1000=P19),1),"")} -> 0 | Y19: {=IFERROR(INDEX(_xlfn._xlws.FILTER($J$7:$J$1000-$I$7:$I$1000,$L$7:$L$1000=P19),2),"")} | Z19: =SUM(V19:Y19) -> 3 | AA19: {=1+SUMPRODUCT(($U$19:$U$22>U19)+(($U$19:$U$22=U19)*($Z$19:$Z$22>Z19)))} -> 1 | AC19: D | AD19: 1 | AE19: {=IFERROR(_xlfn.TEXTJOIN(" - ",TRUE,_xlfn._xlws.FILTER($P$19:$P$22,$AA$19:$AA$22=1)),"")} -> Estados Unidos
B20: 15/06/2026 | C20: 13:00 | D20: Bélgica vs Egipto | E20: Estadio Seattle (Seattle) | F20: {=_xlfn.XLOOKUP(TRUE,(GRUPOS!$B$40:$B$51=G20)+(GRUPOS!$C$40:$C$51=G20)+(GRUPOS!$D$40:$D$51=G20)+(GRUPOS!$E$40:$E$51=G20)>0,GRUPOS!$A$40:$A$51)} -> G | G20: =LEFT(D20,FIND(" vs ",D20)-1) -> Bélgica | L20: =MID(D20,FIND(" vs ",D20)+4,LEN(D20)) -> Egipto | M20: {=_xlfn.XLOOKUP(TRUE,(GRUPOS!$B$40:$B$51=L20)+(GRUPOS!$C$40:$C$51=L20)+(GRUPOS!$D$40:$D$51=L20)+(GRUPOS!$E$40:$E$51=L20)>0,GRUPOS!$A$40:$A$51)} -> G | O20: D | P20: Paraguay | Q20: {=IFERROR(CHOOSE(MATCH(INDEX(_xlfn._xlws.FILTER($H$7:$H$1000,$G$7:$G$1000=P20),1),{"Perdió","Empató","Ganó"},0),0,1,3),"")} | R20: {=IFERROR(CHOOSE(MATCH(INDEX(_xlfn._xlws.FILTER($H$7:$H$1000,$G$7:$G$1000=P20),2),{"Perdió","Empató","Ganó"},0),0,1,3),"")} | S20: {=IFERROR(CHOOSE(MATCH(INDEX(_xlfn._xlws.FILTER($K$7:$K$1000,$L$7:$L$1000=P20),1),{"Perdió","Empató","Ganó"},0),0,1,3),"")} -> 0 | T20: {=IFERROR(CHOOSE(MATCH(INDEX(_xlfn._xlws.FILTER($K$7:$K$1000,$L$7:$L$1000=P20),2),{"Perdió","Empató","Ganó"},0),0,1,3),"")} | U20: =SUM(Q20:S20) -> 0 | V20: {=IFERROR(INDEX(_xlfn._xlws.FILTER($I$7:$I$1000-$J$7:$J$1000,$G$7:$G$1000=P20),1),"")} -> 0 | W20: {=IFERROR(INDEX(_xlfn._xlws.FILTER($I$7:$I$1000-$J$7:$J$1000,$G$7:$G$1000=P20),2),"")} | X20: {=IFERROR(INDEX(_xlfn._xlws.FILTER($J$7:$J$1000-$I$7:$I$1000,$L$7:$L$1000=P20),1),"")} -> -3 | Y20: {=IFERROR(INDEX(_xlfn._xlws.FILTER($J$7:$J$1000-$I$7:$I$1000,$L$7:$L$1000=P20),2),"")} -> 0 | Z20: =SUM(V20:Y20) -> -3 | AA20: {=1+SUMPRODUCT(($U$19:$U$22>U20)+(($U$19:$U$22=U20)*($Z$19:$Z$22>Z20)))} -> 4 | AC20: D | AD20: 2 | AE20: {=IFERROR(_xlfn.TEXTJOIN(" - ",TRUE,_xlfn._xlws.FILTER($P$19:$P$22,$AA$19:$AA$22=2)),"")} -> Australia
B21: 15/06/2026 | C21: 16:00 | D21: Arabia Saudita vs Uruguay | E21: Estadio Miami (Miami) | F21: {=_xlfn.XLOOKUP(TRUE,(GRUPOS!$B$40:$B$51=G21)+(GRUPOS!$C$40:$C$51=G21)+(GRUPOS!$D$40:$D$51=G21)+(GRUPOS!$E$40:$E$51=G21)>0,GRUPOS!$A$40:$A$51)} -> H | G21: =LEFT(D21,FIND(" vs ",D21)-1) -> Arabia Saudita | L21: =MID(D21,FIND(" vs ",D21)+4,LEN(D21)) -> Uruguay | M21: {=_xlfn.XLOOKUP(TRUE,(GRUPOS!$B$40:$B$51=L21)+(GRUPOS!$C$40:$C$51=L21)+(GRUPOS!$D$40:$D$51=L21)+(GRUPOS!$E$40:$E$51=L21)>0,GRUPOS!$A$40:$A$51)} -> H | O21: D | P21: Australia | Q21: {=IFERROR(CHOOSE(MATCH(INDEX(_xlfn._xlws.FILTER($H$7:$H$1000,$G$7:$G$1000=P21),1),{"Perdió","Empató","Ganó"},0),0,1,3),"")} -> 3 | R21: {=IFERROR(CHOOSE(MATCH(INDEX(_xlfn._xlws.FILTER($H$7:$H$1000,$G$7:$G$1000=P21),2),{"Perdió","Empató","Ganó"},0),0,1,3),"")} | S21: {=IFERROR(CHOOSE(MATCH(INDEX(_xlfn._xlws.FILTER($K$7:$K$1000,$L$7:$L$1000=P21),1),{"Perdió","Empató","Ganó"},0),0,1,3),"")} | T21: {=IFERROR(CHOOSE(MATCH(INDEX(_xlfn._xlws.FILTER($K$7:$K$1000,$L$7:$L$1000=P21),2),{"Perdió","Empató","Ganó"},0),0,1,3),"")} | U21: =SUM(Q21:S21) -> 3 | V21: {=IFERROR(INDEX(_xlfn._xlws.FILTER($I$7:$I$1000-$J$7:$J$1000,$G$7:$G$1000=P21),1),"")} -> 2 | W21: {=IFERROR(INDEX(_xlfn._xlws.FILTER($I$7:$I$1000-$J$7:$J$1000,$G$7:$G$1000=P21),2),"")} | X21: {=IFERROR(INDEX(_xlfn._xlws.FILTER($J$7:$J$1000-$I$7:$I$1000,$L$7:$L$1000=P21),1),"")} -> 0 | Y21: {=IFERROR(INDEX(_xlfn._xlws.FILTER($J$7:$J$1000-$I$7:$I$1000,$L$7:$L$1000=P21),2),"")} -> 0 | Z21: =SUM(V21:Y21) -> 2 | AA21: {=1+SUMPRODUCT(($U$19:$U$22>U21)+(($U$19:$U$22=U21)*($Z$19:$Z$22>Z21)))} -> 2 | AC21: D | AD21: 3 | AE21: {=IFERROR(_xlfn.TEXTJOIN(" - ",TRUE,_xlfn._xlws.FILTER($P$19:$P$22,$AA$19:$AA$22=3)),"")} -> Turquía
B22: 15/06/2026 | C22: 19:00 | D22: Irán vs Nueva Zelanda | E22: Estadio Los Ángeles (Los Ángeles) | F22: {=_xlfn.XLOOKUP(TRUE,(GRUPOS!$B$40:$B$51=G22)+(GRUPOS!$C$40:$C$51=G22)+(GRUPOS!$D$40:$D$51=G22)+(GRUPOS!$E$40:$E$51=G22)>0,GRUPOS!$A$40:$A$51)} -> G | G22: =LEFT(D22,FIND(" vs ",D22)-1) -> Irán | L22: =MID(D22,FIND(" vs ",D22)+4,LEN(D22)) -> Nueva Zelanda | M22: {=_xlfn.XLOOKUP(TRUE,(GRUPOS!$B$40:$B$51=L22)+(GRUPOS!$C$40:$C$51=L22)+(GRUPOS!$D$40:$D$51=L22)+(GRUPOS!$E$40:$E$51=L22)>0,GRUPOS!$A$40:$A$51)} -> G | O22: D | P22: Turquía | Q22: {=IFERROR(CHOOSE(MATCH(INDEX(_xlfn._xlws.FILTER($H$7:$H$1000,$G$7:$G$1000=P22),1),{"Perdió","Empató","Ganó"},0),0,1,3),"")} | R22: {=IFERROR(CHOOSE(MATCH(INDEX(_xlfn._xlws.FILTER($H$7:$H$1000,$G$7:$G$1000=P22),2),{"Perdió","Empató","Ganó"},0),0,1,3),"")} | S22: {=IFERROR(CHOOSE(MATCH(INDEX(_xlfn._xlws.FILTER($K$7:$K$1000,$L$7:$L$1000=P22),1),{"Perdió","Empató","Ganó"},0),0,1,3),"")} -> 0 | T22: {=IFERROR(CHOOSE(MATCH(INDEX(_xlfn._xlws.FILTER($K$7:$K$1000,$L$7:$L$1000=P22),2),{"Perdió","Empató","Ganó"},0),0,1,3),"")} | U22: =SUM(Q22:S22) -> 0 | V22: {=IFERROR(INDEX(_xlfn._xlws.FILTER($I$7:$I$1000-$J$7:$J$1000,$G$7:$G$1000=P22),1),"")} -> 0 | W22: {=IFERROR(INDEX(_xlfn._xlws.FILTER($I$7:$I$1000-$J$7:$J$1000,$G$7:$G$1000=P22),2),"")} -> 0 | X22: {=IFERROR(INDEX(_xlfn._xlws.FILTER($J$7:$J$1000-$I$7:$I$1000,$L$7:$L$1000=P22),1),"")} -> -2 | Y22: {=IFERROR(INDEX(_xlfn._xlws.FILTER($J$7:$J$1000-$I$7:$I$1000,$L$7:$L$1000=P22),2),"")} | Z22: =SUM(V22:Y22) -> -2 | AA22: {=1+SUMPRODUCT(($U$19:$U$22>U22)+(($U$19:$U$22=U22)*($Z$19:$Z$22>Z22)))} -> 3 | AC22: D | AD22: 4 | AE22: {=IFERROR(_xlfn.TEXTJOIN(" - ",TRUE,_xlfn._xlws.FILTER($P$19:$P$22,$AA$19:$AA$22=4)),"")} -> Paraguay
B23: 16/06/2026 | C23: 13:00 | D23: Francia vs Senegal | E23: Estadio Nueva York/Nueva Jersey | F23: {=_xlfn.XLOOKUP(TRUE,(GRUPOS!$B$40:$B$51=G23)+(GRUPOS!$C$40:$C$51=G23)+(GRUPOS!$D$40:$D$51=G23)+(GRUPOS!$E$40:$E$51=G23)>0,GRUPOS!$A$40:$A$51)} -> I | G23: =LEFT(D23,FIND(" vs ",D23)-1) -> Francia | L23: =MID(D23,FIND(" vs ",D23)+4,LEN(D23)) -> Senegal | M23: {=_xlfn.XLOOKUP(TRUE,(GRUPOS!$B$40:$B$51=L23)+(GRUPOS!$C$40:$C$51=L23)+(GRUPOS!$D$40:$D$51=L23)+(GRUPOS!$E$40:$E$51=L23)>0,GRUPOS!$A$40:$A$51)} -> I | O23: E | P23: Alemania | Q23: {=IFERROR(CHOOSE(MATCH(INDEX(_xlfn._xlws.FILTER($H$7:$H$1000,$G$7:$G$1000=P23),1),{"Perdió","Empató","Ganó"},0),0,1,3),"")} -> 3 | R23: {=IFERROR(CHOOSE(MATCH(INDEX(_xlfn._xlws.FILTER($H$7:$H$1000,$G$7:$G$1000=P23),2),{"Perdió","Empató","Ganó"},0),0,1,3),"")} | S23: {=IFERROR(CHOOSE(MATCH(INDEX(_xlfn._xlws.FILTER($K$7:$K$1000,$L$7:$L$1000=P23),1),{"Perdió","Empató","Ganó"},0),0,1,3),"")} | T23: {=IFERROR(CHOOSE(MATCH(INDEX(_xlfn._xlws.FILTER($K$7:$K$1000,$L$7:$L$1000=P23),2),{"Perdió","Empató","Ganó"},0),0,1,3),"")} | U23: =SUM(Q23:S23) -> 3 | V23: {=IFERROR(INDEX(_xlfn._xlws.FILTER($I$7:$I$1000-$J$7:$J$1000,$G$7:$G$1000=P23),1),"")} -> 6 | W23: {=IFERROR(INDEX(_xlfn._xlws.FILTER($I$7:$I$1000-$J$7:$J$1000,$G$7:$G$1000=P23),2),"")} -> 0 | X23: {=IFERROR(INDEX(_xlfn._xlws.FILTER($J$7:$J$1000-$I$7:$I$1000,$L$7:$L$1000=P23),1),"")} -> 0 | Y23: {=IFERROR(INDEX(_xlfn._xlws.FILTER($J$7:$J$1000-$I$7:$I$1000,$L$7:$L$1000=P23),2),"")} | Z23: =SUM(V23:Y23) -> 6 | AA23: {=1+SUMPRODUCT(($U$23:$U$26>U23)+(($U$23:$U$26=U23)*($Z$23:$Z$26>Z23)))} -> 1 | AC23: E | AD23: 1 | AE23: {=IFERROR(_xlfn.TEXTJOIN(" - ",TRUE,_xlfn._xlws.FILTER($P$19:$P$22,$AA$19:$AA$22=1)),"")} -> Estados Unidos
B24: 16/06/2026 | C24: 16:00 | D24: Irak vs Noruega | E24: Estadio Boston (Boston) | F24: {=_xlfn.XLOOKUP(TRUE,(GRUPOS!$B$40:$B$51=G24)+(GRUPOS!$C$40:$C$51=G24)+(GRUPOS!$D$40:$D$51=G24)+(GRUPOS!$E$40:$E$51=G24)>0,GRUPOS!$A$40:$A$51)} -> I | G24: =LEFT(D24,FIND(" vs ",D24)-1) -> Irak | L24: =MID(D24,FIND(" vs ",D24)+4,LEN(D24)) -> Noruega | M24: {=_xlfn.XLOOKUP(TRUE,(GRUPOS!$B$40:$B$51=L24)+(GRUPOS!$C$40:$C$51=L24)+(GRUPOS!$D$40:$D$51=L24)+(GRUPOS!$E$40:$E$51=L24)>0,GRUPOS!$A$40:$A$51)} -> I | O24: E | P24: Curazao | Q24: {=IFERROR(CHOOSE(MATCH(INDEX(_xlfn._xlws.FILTER($H$7:$H$1000,$G$7:$G$1000=P24),1),{"Perdió","Empató","Ganó"},0),0,1,3),"")} | R24: {=IFERROR(CHOOSE(MATCH(INDEX(_xlfn._xlws.FILTER($H$7:$H$1000,$G$7:$G$1000=P24),2),{"Perdió","Empató","Ganó"},0),0,1,3),"")} | S24: {=IFERROR(CHOOSE(MATCH(INDEX(_xlfn._xlws.FILTER($K$7:$K$1000,$L$7:$L$1000=P24),1),{"Perdió","Empató","Ganó"},0),0,1,3),"")} -> 0 | T24: {=IFERROR(CHOOSE(MATCH(INDEX(_xlfn._xlws.FILTER($K$7:$K$1000,$L$7:$L$1000=P24),2),{"Perdió","Empató","Ganó"},0),0,1,3),"")} | U24: =SUM(Q24:S24) -> 0 | V24: {=IFERROR(INDEX(_xlfn._xlws.FILTER($I$7:$I$1000-$J$7:$J$1000,$G$7:$G$1000=P24),1),"")} -> 0 | W24: {=IFERROR(INDEX(_xlfn._xlws.FILTER($I$7:$I$1000-$J$7:$J$1000,$G$7:$G$1000=P24),2),"")} | X24: {=IFERROR(INDEX(_xlfn._xlws.FILTER($J$7:$J$1000-$I$7:$I$1000,$L$7:$L$1000=P24),1),"")} -> -6 | Y24: {=IFERROR(INDEX(_xlfn._xlws.FILTER($J$7:$J$1000-$I$7:$I$1000,$L$7:$L$1000=P24),2),"")} -> 0 | Z24: =SUM(V24:Y24) -> -6 | AA24: {=1+SUMPRODUCT(($U$23:$U$26>U24)+(($U$23:$U$26=U24)*($Z$23:$Z$26>Z24)))} -> 4 | AC24: E | AD24: 2 | AE24: {=IFERROR(_xlfn.TEXTJOIN(" - ",TRUE,_xlfn._xlws.FILTER($P$19:$P$22,$AA$19:$AA$22=2)),"")} -> Australia
B25: 16/06/2026 | C25: 19:00 | D25: Argentina vs Argelia | E25: Estadio Kansas City | F25: {=_xlfn.XLOOKUP(TRUE,(GRUPOS!$B$40:$B$51=G25)+(GRUPOS!$C$40:$C$51=G25)+(GRUPOS!$D$40:$D$51=G25)+(GRUPOS!$E$40:$E$51=G25)>0,GRUPOS!$A$40:$A$51)} -> J | G25: =LEFT(D25,FIND(" vs ",D25)-1) -> Argentina | L25: =MID(D25,FIND(" vs ",D25)+4,LEN(D25)) -> Argelia | M25: {=_xlfn.XLOOKUP(TRUE,(GRUPOS!$B$40:$B$51=L25)+(GRUPOS!$C$40:$C$51=L25)+(GRUPOS!$D$40:$D$51=L25)+(GRUPOS!$E$40:$E$51=L25)>0,GRUPOS!$A$40:$A$51)} -> J | O25: E | P25: Costa de Marfil | Q25: {=IFERROR(CHOOSE(MATCH(INDEX(_xlfn._xlws.FILTER($H$7:$H$1000,$G$7:$G$1000=P25),1),{"Perdió","Empató","Ganó"},0),0,1,3),"")} -> 3 | R25: {=IFERROR(CHOOSE(MATCH(INDEX(_xlfn._xlws.FILTER($H$7:$H$1000,$G$7:$G$1000=P25),2),{"Perdió","Empató","Ganó"},0),0,1,3),"")} | S25: {=IFERROR(CHOOSE(MATCH(INDEX(_xlfn._xlws.FILTER($K$7:$K$1000,$L$7:$L$1000=P25),1),{"Perdió","Empató","Ganó"},0),0,1,3),"")} | T25: {=IFERROR(CHOOSE(MATCH(INDEX(_xlfn._xlws.FILTER($K$7:$K$1000,$L$7:$L$1000=P25),2),{"Perdió","Empató","Ganó"},0),0,1,3),"")} | U25: =SUM(Q25:S25) -> 3 | V25: {=IFERROR(INDEX(_xlfn._xlws.FILTER($I$7:$I$1000-$J$7:$J$1000,$G$7:$G$1000=P25),1),"")} -> 1 | W25: {=IFERROR(INDEX(_xlfn._xlws.FILTER($I$7:$I$1000-$J$7:$J$1000,$G$7:$G$1000=P25),2),"")} | X25: {=IFERROR(INDEX(_xlfn._xlws.FILTER($J$7:$J$1000-$I$7:$I$1000,$L$7:$L$1000=P25),1),"")} -> 0 | Y25: {=IFERROR(INDEX(_xlfn._xlws.FILTER($J$7:$J$1000-$I$7:$I$1000,$L$7:$L$1000=P25),2),"")} -> 0 | Z25: =SUM(V25:Y25) -> 1 | AA25: {=1+SUMPRODUCT(($U$23:$U$26>U25)+(($U$23:$U$26=U25)*($Z$23:$Z$26>Z25)))} -> 2 | AC25: E | AD25: 3 | AE25: {=IFERROR(_xlfn.TEXTJOIN(" - ",TRUE,_xlfn._xlws.FILTER($P$19:$P$22,$AA$19:$AA$22=3)),"")} -> Turquía
B26: 16/06/2026 | C26: 22:00 | D26: Austria vs Jordania | E26: Estadio Bahía de San Francisco | F26: {=_xlfn.XLOOKUP(TRUE,(GRUPOS!$B$40:$B$51=G26)+(GRUPOS!$C$40:$C$51=G26)+(GRUPOS!$D$40:$D$51=G26)+(GRUPOS!$E$40:$E$51=G26)>0,GRUPOS!$A$40:$A$51)} -> J | G26: =LEFT(D26,FIND(" vs ",D26)-1) -> Austria | L26: =MID(D26,FIND(" vs ",D26)+4,LEN(D26)) -> Jordania | M26: {=_xlfn.XLOOKUP(TRUE,(GRUPOS!$B$40:$B$51=L26)+(GRUPOS!$C$40:$C$51=L26)+(GRUPOS!$D$40:$D$51=L26)+(GRUPOS!$E$40:$E$51=L26)>0,GRUPOS!$A$40:$A$51)} -> J | O26: E | P26: Ecuador | Q26: {=IFERROR(CHOOSE(MATCH(INDEX(_xlfn._xlws.FILTER($H$7:$H$1000,$G$7:$G$1000=P26),1),{"Perdió","Empató","Ganó"},0),0,1,3),"")} | R26: {=IFERROR(CHOOSE(MATCH(INDEX(_xlfn._xlws.FILTER($H$7:$H$1000,$G$7:$G$1000=P26),2),{"Perdió","Empató","Ganó"},0),0,1,3),"")} | S26: {=IFERROR(CHOOSE(MATCH(INDEX(_xlfn._xlws.FILTER($K$7:$K$1000,$L$7:$L$1000=P26),1),{"Perdió","Empató","Ganó"},0),0,1,3),"")} -> 0 | T26: {=IFERROR(CHOOSE(MATCH(INDEX(_xlfn._xlws.FILTER($K$7:$K$1000,$L$7:$L$1000=P26),2),{"Perdió","Empató","Ganó"},0),0,1,3),"")} | U26: =SUM(Q26:S26) -> 0 | V26: {=IFERROR(INDEX(_xlfn._xlws.FILTER($I$7:$I$1000-$J$7:$J$1000,$G$7:$G$1000=P26),1),"")} -> 0 | W26: {=IFERROR(INDEX(_xlfn._xlws.FILTER($I$7:$I$1000-$J$7:$J$1000,$G$7:$G$1000=P26),2),"")} -> 0 | X26: {=IFERROR(INDEX(_xlfn._xlws.FILTER($J$7:$J$1000-$I$7:$I$1000,$L$7:$L$1000=P26),1),"")} -> -1 | Y26: {=IFERROR(INDEX(_xlfn._xlws.FILTER($J$7:$J$1000-$I$7:$I$1000,$L$7:$L$1000=P26),2),"")} | Z26: =SUM(V26:Y26) -> -1 | AA26: {=1+SUMPRODUCT(($U$23:$U$26>U26)+(($U$23:$U$26=U26)*($Z$23:$Z$26>Z26)))} -> 3 | AC26: E | AD26: 4 | AE26: {=IFERROR(_xlfn.TEXTJOIN(" - ",TRUE,_xlfn._xlws.FILTER($P$19:$P$22,$AA$19:$AA$22=4)),"")} -> Paraguay
B27: 17/06/2026 | C27: 11:00 | D27: Portugal vs RD Congo | E27: Estadio Houston | F27: {=_xlfn.XLOOKUP(TRUE,(GRUPOS!$B$40:$B$51=G27)+(GRUPOS!$C$40:$C$51=G27)+(GRUPOS!$D$40:$D$51=G27)+(GRUPOS!$E$40:$E$51=G27)>0,GRUPOS!$A$40:$A$51)} -> K | G27: =LEFT(D27,FIND(" vs ",D27)-1) -> Portugal | L27: =MID(D27,FIND(" vs ",D27)+4,LEN(D27)) -> RD Congo | M27: {=_xlfn.XLOOKUP(TRUE,(GRUPOS!$B$40:$B$51=L27)+(GRUPOS!$C$40:$C$51=L27)+(GRUPOS!$D$40:$D$51=L27)+(GRUPOS!$E$40:$E$51=L27)>0,GRUPOS!$A$40:$A$51)} -> K | O27: F | P27: Países Bajos | Q27: {=IFERROR(CHOOSE(MATCH(INDEX(_xlfn._xlws.FILTER($H$7:$H$1000,$G$7:$G$1000=P27),1),{"Perdió","Empató","Ganó"},0),0,1,3),"")} -> 1 | R27: {=IFERROR(CHOOSE(MATCH(INDEX(_xlfn._xlws.FILTER($H$7:$H$1000,$G$7:$G$1000=P27),2),{"Perdió","Empató","Ganó"},0),0,1,3),"")} | S27: {=IFERROR(CHOOSE(MATCH(INDEX(_xlfn._xlws.FILTER($K$7:$K$1000,$L$7:$L$1000=P27),1),{"Perdió","Empató","Ganó"},0),0,1,3),"")} | T27: {=IFERROR(CHOOSE(MATCH(INDEX(_xlfn._xlws.FILTER($K$7:$K$1000,$L$7:$L$1000=P27),2),{"Perdió","Empató","Ganó"},0),0,1,3),"")} | U27: =SUM(Q27:S27) -> 1 | V27: {=IFERROR(INDEX(_xlfn._xlws.FILTER($I$7:$I$1000-$J$7:$J$1000,$G$7:$G$1000=P27),1),"")} -> 0 | W27: {=IFERROR(INDEX(_xlfn._xlws.FILTER($I$7:$I$1000-$J$7:$J$1000,$G$7:$G$1000=P27),2),"")} -> 0 | X27: {=IFERROR(INDEX(_xlfn._xlws.FILTER($J$7:$J$1000-$I$7:$I$1000,$L$7:$L$1000=P27),1),"")} -> 0 | Y27: {=IFERROR(INDEX(_xlfn._xlws.FILTER($J$7:$J$1000-$I$7:$I$1000,$L$7:$L$1000=P27),2),"")} | Z27: =SUM(V27:Y27) -> 0 | AA27: {=1+SUMPRODUCT(($U$27:$U$30>U27)+(($U$27:$U$30=U27)*($Z$27:$Z$30>Z27)))} -> 1 | AC27: F | AD27: 1 | AE27: {=IFERROR(_xlfn.TEXTJOIN(" - ",TRUE,_xlfn._xlws.FILTER($P$27:$P$30,$AA$27:$AA$30=1)),"")} -> Países Bajos - Japón
B28: 17/06/2026 | C28: 14:00 | D28: Inglaterra vs Croacia | E28: Estadio Dallas | F28: {=_xlfn.XLOOKUP(TRUE,(GRUPOS!$B$40:$B$51=G28)+(GRUPOS!$C$40:$C$51=G28)+(GRUPOS!$D$40:$D$51=G28)+(GRUPOS!$E$40:$E$51=G28)>0,GRUPOS!$A$40:$A$51)} -> L | G28: =LEFT(D28,FIND(" vs ",D28)-1) -> Inglaterra | L28: =MID(D28,FIND(" vs ",D28)+4,LEN(D28)) -> Croacia | M28: {=_xlfn.XLOOKUP(TRUE,(GRUPOS!$B$40:$B$51=L28)+(GRUPOS!$C$40:$C$51=L28)+(GRUPOS!$D$40:$D$51=L28)+(GRUPOS!$E$40:$E$51=L28)>0,GRUPOS!$A$40:$A$51)} -> L | O28: F | P28: Japón | Q28: {=IFERROR(CHOOSE(MATCH(INDEX(_xlfn._xlws.FILTER($H$7:$H$1000,$G$7:$G$1000=P28),1),{"Perdió","Empató","Ganó"},0),0,1,3),"")} | R28: {=IFERROR(CHOOSE(MATCH(INDEX(_xlfn._xlws.FILTER($H$7:$H$1000,$G$7:$G$1000=P28),2),{"Perdió","Empató","Ganó"},0),0,1,3),"")} | S28: {=IFERROR(CHOOSE(MATCH(INDEX(_xlfn._xlws.FILTER($K$7:$K$1000,$L$7:$L$1000=P28),1),{"Perdió","Empató","Ganó"},0),0,1,3),"")} -> 1 | T28: {=IFERROR(CHOOSE(MATCH(INDEX(_xlfn._xlws.FILTER($K$7:$K$1000,$L$7:$L$1000=P28),2),{"Perdió","Empató","Ganó"},0),0,1,3),"")} | U28: =SUM(Q28:S28) -> 1 | V28: {=IFERROR(INDEX(_xlfn._xlws.FILTER($I$7:$I$1000-$J$7:$J$1000,$G$7:$G$1000=P28),1),"")} -> 0 | W28: {=IFERROR(INDEX(_xlfn._xlws.FILTER($I$7:$I$1000-$J$7:$J$1000,$G$7:$G$1000=P28),2),"")} | X28: {=IFERROR(INDEX(_xlfn._xlws.FILTER($J$7:$J$1000-$I$7:$I$1000,$L$7:$L$1000=P28),1),"")} -> 0 | Y28: {=IFERROR(INDEX(_xlfn._xlws.FILTER($J$7:$J$1000-$I$7:$I$1000,$L$7:$L$1000=P28),2),"")} -> 0 | Z28: =SUM(V28:Y28) -> 0 | AA28: {=1+SUMPRODUCT(($U$27:$U$30>U28)+(($U$27:$U$30=U28)*($Z$27:$Z$30>Z28)))} -> 1 | AC28: F | AD28: 2 | AE28: {=IFERROR(_xlfn.TEXTJOIN(" - ",TRUE,_xlfn._xlws.FILTER($P$27:$P$30,$AA$27:$AA$30=2)),"")}
B29: 17/06/2026 | C29: 17:00 | D29: Ghana vs Panamá | E29: Estadio Toronto | F29: {=_xlfn.XLOOKUP(TRUE,(GRUPOS!$B$40:$B$51=G29)+(GRUPOS!$C$40:$C$51=G29)+(GRUPOS!$D$40:$D$51=G29)+(GRUPOS!$E$40:$E$51=G29)>0,GRUPOS!$A$40:$A$51)} -> L | G29: =LEFT(D29,FIND(" vs ",D29)-1) -> Ghana | L29: =MID(D29,FIND(" vs ",D29)+4,LEN(D29)) -> Panamá | M29: {=_xlfn.XLOOKUP(TRUE,(GRUPOS!$B$40:$B$51=L29)+(GRUPOS!$C$40:$C$51=L29)+(GRUPOS!$D$40:$D$51=L29)+(GRUPOS!$E$40:$E$51=L29)>0,GRUPOS!$A$40:$A$51)} -> L | O29: F | P29: Suecia | Q29: {=IFERROR(CHOOSE(MATCH(INDEX(_xlfn._xlws.FILTER($H$7:$H$1000,$G$7:$G$1000=P29),1),{"Perdió","Empató","Ganó"},0),0,1,3),"")} | R29: {=IFERROR(CHOOSE(MATCH(INDEX(_xlfn._xlws.FILTER($H$7:$H$1000,$G$7:$G$1000=P29),2),{"Perdió","Empató","Ganó"},0),0,1,3),"")} | S29: {=IFERROR(CHOOSE(MATCH(INDEX(_xlfn._xlws.FILTER($K$7:$K$1000,$L$7:$L$1000=P29),1),{"Perdió","Empató","Ganó"},0),0,1,3),"")} | T29: {=IFERROR(CHOOSE(MATCH(INDEX(_xlfn._xlws.FILTER($K$7:$K$1000,$L$7:$L$1000=P29),2),{"Perdió","Empató","Ganó"},0),0,1,3),"")} | U29: =SUM(Q29:S29) -> 0 | V29: {=IFERROR(INDEX(_xlfn._xlws.FILTER($I$7:$I$1000-$J$7:$J$1000,$G$7:$G$1000=P29),1),"")} -> 0 | W29: {=IFERROR(INDEX(_xlfn._xlws.FILTER($I$7:$I$1000-$J$7:$J$1000,$G$7:$G$1000=P29),2),"")} | X29: {=IFERROR(INDEX(_xlfn._xlws.FILTER($J$7:$J$1000-$I$7:$I$1000,$L$7:$L$1000=P29),1),"")} -> 0 | Y29: {=IFERROR(INDEX(_xlfn._xlws.FILTER($J$7:$J$1000-$I$7:$I$1000,$L$7:$L$1000=P29),2),"")} -> 0 | Z29: =SUM(V29:Y29) -> 0 | AA29: {=1+SUMPRODUCT(($U$27:$U$30>U29)+(($U$27:$U$30=U29)*($Z$27:$Z$30>Z29)))} -> 3 | AC29: F | AD29: 3 | AE29: {=IFERROR(_xlfn.TEXTJOIN(" - ",TRUE,_xlfn._xlws.FILTER($P$27:$P$30,$AA$27:$AA$30=3)),"")} -> Suecia - Túnez
B30: 17/06/2026 | C30: 20:00 | D30: Uzbekistán vs Colombia | E30: Estadio Ciudad de México | F30: {=_xlfn.XLOOKUP(TRUE,(GRUPOS!$B$40:$B$51=G30)+(GRUPOS!$C$40:$C$51=G30)+(GRUPOS!$D$40:$D$51=G30)+(GRUPOS!$E$40:$E$51=G30)>0,GRUPOS!$A$40:$A$51)} -> K | G30: =LEFT(D30,FIND(" vs ",D30)-1) -> Uzbekistán | L30: =MID(D30,FIND(" vs ",D30)+4,LEN(D30)) -> Colombia | M30: {=_xlfn.XLOOKUP(TRUE,(GRUPOS!$B$40:$B$51=L30)+(GRUPOS!$C$40:$C$51=L30)+(GRUPOS!$D$40:$D$51=L30)+(GRUPOS!$E$40:$E$51=L30)>0,GRUPOS!$A$40:$A$51)} -> K | O30: F | P30: Túnez | Q30: {=IFERROR(CHOOSE(MATCH(INDEX(_xlfn._xlws.FILTER($H$7:$H$1000,$G$7:$G$1000=P30),1),{"Perdió","Empató","Ganó"},0),0,1,3),"")} | R30: {=IFERROR(CHOOSE(MATCH(INDEX(_xlfn._xlws.FILTER($H$7:$H$1000,$G$7:$G$1000=P30),2),{"Perdió","Empató","Ganó"},0),0,1,3),"")} | S30: {=IFERROR(CHOOSE(MATCH(INDEX(_xlfn._xlws.FILTER($K$7:$K$1000,$L$7:$L$1000=P30),1),{"Perdió","Empató","Ganó"},0),0,1,3),"")} | T30: {=IFERROR(CHOOSE(MATCH(INDEX(_xlfn._xlws.FILTER($K$7:$K$1000,$L$7:$L$1000=P30),2),{"Perdió","Empató","Ganó"},0),0,1,3),"")} | U30: =SUM(Q30:S30) -> 0 | V30: {=IFERROR(INDEX(_xlfn._xlws.FILTER($I$7:$I$1000-$J$7:$J$1000,$G$7:$G$1000=P30),1),"")} -> 0 | W30: {=IFERROR(INDEX(_xlfn._xlws.FILTER($I$7:$I$1000-$J$7:$J$1000,$G$7:$G$1000=P30),2),"")} -> 0 | X30: {=IFERROR(INDEX(_xlfn._xlws.FILTER($J$7:$J$1000-$I$7:$I$1000,$L$7:$L$1000=P30),1),"")} -> 0 | Y30: {=IFERROR(INDEX(_xlfn._xlws.FILTER($J$7:$J$1000-$I$7:$I$1000,$L$7:$L$1000=P30),2),"")} | Z30: =SUM(V30:Y30) -> 0 | AA30: {=1+SUMPRODUCT(($U$27:$U$30>U30)+(($U$27:$U$30=U30)*($Z$27:$Z$30>Z30)))} -> 3 | AC30: F | AD30: 4 | AE30: {=IFERROR(_xlfn.TEXTJOIN(" - ",TRUE,_xlfn._xlws.FILTER($P$27:$P$30,$AA$27:$AA$30=4)),"")}
B31: 18/06/2026 | C31: 10:00 | D31: Chequia vs Sudáfrica | E31: Estadio Atlanta | F31: {=_xlfn.XLOOKUP(TRUE,(GRUPOS!$B$40:$B$51=G31)+(GRUPOS!$C$40:$C$51=G31)+(GRUPOS!$D$40:$D$51=G31)+(GRUPOS!$E$40:$E$51=G31)>0,GRUPOS!$A$40:$A$51)} -> A | G31: =LEFT(D31,FIND(" vs ",D31)-1) -> Chequia | L31: =MID(D31,FIND(" vs ",D31)+4,LEN(D31)) -> Sudáfrica | M31: {=_xlfn.XLOOKUP(TRUE,(GRUPOS!$B$40:$B$51=L31)+(GRUPOS!$C$40:$C$51=L31)+(GRUPOS!$D$40:$D$51=L31)+(GRUPOS!$E$40:$E$51=L31)>0,GRUPOS!$A$40:$A$51)} -> A | O31: G | P31: Bélgica | Q31: {=IFERROR(CHOOSE(MATCH(INDEX(_xlfn._xlws.FILTER($H$7:$H$1000,$G$7:$G$1000=P31),1),{"Perdió","Empató","Ganó"},0),0,1,3),"")} | R31: {=IFERROR(CHOOSE(MATCH(INDEX(_xlfn._xlws.FILTER($H$7:$H$1000,$G$7:$G$1000=P31),2),{"Perdió","Empató","Ganó"},0),0,1,3),"")} | S31: {=IFERROR(CHOOSE(MATCH(INDEX(_xlfn._xlws.FILTER($K$7:$K$1000,$L$7:$L$1000=P31),1),{"Perdió","Empató","Ganó"},0),0,1,3),"")} | T31: {=IFERROR(CHOOSE(MATCH(INDEX(_xlfn._xlws.FILTER($K$7:$K$1000,$L$7:$L$1000=P31),2),{"Perdió","Empató","Ganó"},0),0,1,3),"")} | U31: =SUM(Q31:S31) -> 0 | V31: {=IFERROR(INDEX(_xlfn._xlws.FILTER($I$7:$I$1000-$J$7:$J$1000,$G$7:$G$1000=P31),1),"")} -> 0 | W31: {=IFERROR(INDEX(_xlfn._xlws.FILTER($I$7:$I$1000-$J$7:$J$1000,$G$7:$G$1000=P31),2),"")} -> 0 | X31: {=IFERROR(INDEX(_xlfn._xlws.FILTER($J$7:$J$1000-$I$7:$I$1000,$L$7:$L$1000=P31),1),"")} -> 0 | Y31: {=IFERROR(INDEX(_xlfn._xlws.FILTER($J$7:$J$1000-$I$7:$I$1000,$L$7:$L$1000=P31),2),"")} | Z31: =SUM(V31:Y31) -> 0 | AA31: {=1+SUMPRODUCT(($U$31:$U$34>U31)+(($U$31:$U$34=U31)*($Z$31:$Z$34>Z31)))} -> 1 | AC31: G | AD31: 1 | AE31: {=IFERROR(_xlfn.TEXTJOIN(" - ",TRUE,_xlfn._xlws.FILTER($P$31:$P$34,$AA$31:$AA$34=1)),"")} -> Bélgica - Egipto - Irán - Nueva Zelanda
B32: 18/06/2026 | C32: 13:00 | D32: Suiza vs Bosnia y Herzegovina | E32: Estadio Los Ángeles | F32: {=_xlfn.XLOOKUP(TRUE,(GRUPOS!$B$40:$B$51=G32)+(GRUPOS!$C$40:$C$51=G32)+(GRUPOS!$D$40:$D$51=G32)+(GRUPOS!$E$40:$E$51=G32)>0,GRUPOS!$A$40:$A$51)} -> B | G32: =LEFT(D32,FIND(" vs ",D32)-1) -> Suiza | L32: =MID(D32,FIND(" vs ",D32)+4,LEN(D32)) -> Bosnia y Herzegovina | M32: {=_xlfn.XLOOKUP(TRUE,(GRUPOS!$B$40:$B$51=L32)+(GRUPOS!$C$40:$C$51=L32)+(GRUPOS!$D$40:$D$51=L32)+(GRUPOS!$E$40:$E$51=L32)>0,GRUPOS!$A$40:$A$51)} -> B | O32: G | P32: Egipto | Q32: {=IFERROR(CHOOSE(MATCH(INDEX(_xlfn._xlws.FILTER($H$7:$H$1000,$G$7:$G$1000=P32),1),{"Perdió","Empató","Ganó"},0),0,1,3),"")} | R32: {=IFERROR(CHOOSE(MATCH(INDEX(_xlfn._xlws.FILTER($H$7:$H$1000,$G$7:$G$1000=P32),2),{"Perdió","Empató","Ganó"},0),0,1,3),"")} | S32: {=IFERROR(CHOOSE(MATCH(INDEX(_xlfn._xlws.FILTER($K$7:$K$1000,$L$7:$L$1000=P32),1),{"Perdió","Empató","Ganó"},0),0,1,3),"")} | T32: {=IFERROR(CHOOSE(MATCH(INDEX(_xlfn._xlws.FILTER($K$7:$K$1000,$L$7:$L$1000=P32),2),{"Perdió","Empató","Ganó"},0),0,1,3),"")} | U32: =SUM(Q32:S32) -> 0 | V32: {=IFERROR(INDEX(_xlfn._xlws.FILTER($I$7:$I$1000-$J$7:$J$1000,$G$7:$G$1000=P32),1),"")} -> 0 | W32: {=IFERROR(INDEX(_xlfn._xlws.FILTER($I$7:$I$1000-$J$7:$J$1000,$G$7:$G$1000=P32),2),"")} | X32: {=IFERROR(INDEX(_xlfn._xlws.FILTER($J$7:$J$1000-$I$7:$I$1000,$L$7:$L$1000=P32),1),"")} -> 0 | Y32: {=IFERROR(INDEX(_xlfn._xlws.FILTER($J$7:$J$1000-$I$7:$I$1000,$L$7:$L$1000=P32),2),"")} -> 0 | Z32: =SUM(V32:Y32) -> 0 | AA32: {=1+SUMPRODUCT(($U$31:$U$34>U32)+(($U$31:$U$34=U32)*($Z$31:$Z$34>Z32)))} -> 1 | AC32: G | AD32: 2
B33: 18/06/2026 | C33: 16:00 | D33: Canadá vs Qatar | E33: Estadio Vancouver | F33: {=_xlfn.XLOOKUP(TRUE,(GRUPOS!$B$40:$B$51=G33)+(GRUPOS!$C$40:$C$51=G33)+(GRUPOS!$D$40:$D$51=G33)+(GRUPOS!$E$40:$E$51=G33)>0,GRUPOS!$A$40:$A$51)} -> B | G33: =LEFT(D33,FIND(" vs ",D33)-1) -> Canadá | L33: =MID(D33,FIND(" vs ",D33)+4,LEN(D33)) -> Qatar | M33: {=_xlfn.XLOOKUP(TRUE,(GRUPOS!$B$40:$B$51=L33)+(GRUPOS!$C$40:$C$51=L33)+(GRUPOS!$D$40:$D$51=L33)+(GRUPOS!$E$40:$E$51=L33)>0,GRUPOS!$A$40:$A$51)} -> B | O33: G | P33: Irán | Q33: {=IFERROR(CHOOSE(MATCH(INDEX(_xlfn._xlws.FILTER($H$7:$H$1000,$G$7:$G$1000=P33),1),{"Perdió","Empató","Ganó"},0),0,1,3),"")} | R33: {=IFERROR(CHOOSE(MATCH(INDEX(_xlfn._xlws.FILTER($H$7:$H$1000,$G$7:$G$1000=P33),2),{"Perdió","Empató","Ganó"},0),0,1,3),"")} | S33: {=IFERROR(CHOOSE(MATCH(INDEX(_xlfn._xlws.FILTER($K$7:$K$1000,$L$7:$L$1000=P33),1),{"Perdió","Empató","Ganó"},0),0,1,3),"")} | T33: {=IFERROR(CHOOSE(MATCH(INDEX(_xlfn._xlws.FILTER($K$7:$K$1000,$L$7:$L$1000=P33),2),{"Perdió","Empató","Ganó"},0),0,1,3),"")} | U33: =SUM(Q33:S33) -> 0 | V33: {=IFERROR(INDEX(_xlfn._xlws.FILTER($I$7:$I$1000-$J$7:$J$1000,$G$7:$G$1000=P33),1),"")} -> 0 | W33: {=IFERROR(INDEX(_xlfn._xlws.FILTER($I$7:$I$1000-$J$7:$J$1000,$G$7:$G$1000=P33),2),"")} | X33: {=IFERROR(INDEX(_xlfn._xlws.FILTER($J$7:$J$1000-$I$7:$I$1000,$L$7:$L$1000=P33),1),"")} -> 0 | Y33: {=IFERROR(INDEX(_xlfn._xlws.FILTER($J$7:$J$1000-$I$7:$I$1000,$L$7:$L$1000=P33),2),"")} -> 0 | Z33: =SUM(V33:Y33) -> 0 | AA33: {=1+SUMPRODUCT(($U$31:$U$34>U33)+(($U$31:$U$34=U33)*($Z$31:$Z$34>Z33)))} -> 1 | AC33: G | AD33: 3
B34: 18/06/2026 | C34: 19:00 | D34: México vs Corea del Sur | E34: Estadio Guadalajara | F34: {=_xlfn.XLOOKUP(TRUE,(GRUPOS!$B$40:$B$51=G34)+(GRUPOS!$C$40:$C$51=G34)+(GRUPOS!$D$40:$D$51=G34)+(GRUPOS!$E$40:$E$51=G34)>0,GRUPOS!$A$40:$A$51)} -> A | G34: =LEFT(D34,FIND(" vs ",D34)-1) -> México | L34: =MID(D34,FIND(" vs ",D34)+4,LEN(D34)) -> Corea del Sur | M34: {=_xlfn.XLOOKUP(TRUE,(GRUPOS!$B$40:$B$51=L34)+(GRUPOS!$C$40:$C$51=L34)+(GRUPOS!$D$40:$D$51=L34)+(GRUPOS!$E$40:$E$51=L34)>0,GRUPOS!$A$40:$A$51)} -> A | O34: G | P34: Nueva Zelanda | Q34: {=IFERROR(CHOOSE(MATCH(INDEX(_xlfn._xlws.FILTER($H$7:$H$1000,$G$7:$G$1000=P34),1),{"Perdió","Empató","Ganó"},0),0,1,3),"")} | R34: {=IFERROR(CHOOSE(MATCH(INDEX(_xlfn._xlws.FILTER($H$7:$H$1000,$G$7:$G$1000=P34),2),{"Perdió","Empató","Ganó"},0),0,1,3),"")} | S34: {=IFERROR(CHOOSE(MATCH(INDEX(_xlfn._xlws.FILTER($K$7:$K$1000,$L$7:$L$1000=P34),1),{"Perdió","Empató","Ganó"},0),0,1,3),"")} | T34: {=IFERROR(CHOOSE(MATCH(INDEX(_xlfn._xlws.FILTER($K$7:$K$1000,$L$7:$L$1000=P34),2),{"Perdió","Empató","Ganó"},0),0,1,3),"")} | U34: =SUM(Q34:S34) -> 0 | V34: {=IFERROR(INDEX(_xlfn._xlws.FILTER($I$7:$I$1000-$J$7:$J$1000,$G$7:$G$1000=P34),1),"")} -> 0 | W34: {=IFERROR(INDEX(_xlfn._xlws.FILTER($I$7:$I$1000-$J$7:$J$1000,$G$7:$G$1000=P34),2),"")} -> 0 | X34: {=IFERROR(INDEX(_xlfn._xlws.FILTER($J$7:$J$1000-$I$7:$I$1000,$L$7:$L$1000=P34),1),"")} -> 0 | Y34: {=IFERROR(INDEX(_xlfn._xlws.FILTER($J$7:$J$1000-$I$7:$I$1000,$L$7:$L$1000=P34),2),"")} | Z34: =SUM(V34:Y34) -> 0 | AA34: {=1+SUMPRODUCT(($U$31:$U$34>U34)+(($U$31:$U$34=U34)*($Z$31:$Z$34>Z34)))} -> 1 | AC34: G | AD34: 4
B35: 19/06/2026 | C35: 13:00 | D35: Estados Unidos vs Australia | E35: Estadio Seattle | F35: {=_xlfn.XLOOKUP(TRUE,(GRUPOS!$B$40:$B$51=G35)+(GRUPOS!$C$40:$C$51=G35)+(GRUPOS!$D$40:$D$51=G35)+(GRUPOS!$E$40:$E$51=G35)>0,GRUPOS!$A$40:$A$51)} -> D | G35: =LEFT(D35,FIND(" vs ",D35)-1) -> Estados Unidos | L35: =MID(D35,FIND(" vs ",D35)+4,LEN(D35)) -> Australia | M35: {=_xlfn.XLOOKUP(TRUE,(GRUPOS!$B$40:$B$51=L35)+(GRUPOS!$C$40:$C$51=L35)+(GRUPOS!$D$40:$D$51=L35)+(GRUPOS!$E$40:$E$51=L35)>0,GRUPOS!$A$40:$A$51)} -> D | O35: H | P35: España | Q35: {=IFERROR(CHOOSE(MATCH(INDEX(_xlfn._xlws.FILTER($H$7:$H$1000,$G$7:$G$1000=P35),1),{"Perdió","Empató","Ganó"},0),0,1,3),"")} | R35: {=IFERROR(CHOOSE(MATCH(INDEX(_xlfn._xlws.FILTER($H$7:$H$1000,$G$7:$G$1000=P35),2),{"Perdió","Empató","Ganó"},0),0,1,3),"")} | S35: {=IFERROR(CHOOSE(MATCH(INDEX(_xlfn._xlws.FILTER($K$7:$K$1000,$L$7:$L$1000=P35),1),{"Perdió","Empató","Ganó"},0),0,1,3),"")} | T35: {=IFERROR(CHOOSE(MATCH(INDEX(_xlfn._xlws.FILTER($K$7:$K$1000,$L$7:$L$1000=P35),2),{"Perdió","Empató","Ganó"},0),0,1,3),"")} | U35: =SUM(Q35:S35) -> 0 | V35: {=IFERROR(INDEX(_xlfn._xlws.FILTER($I$7:$I$1000-$J$7:$J$1000,$G$7:$G$1000=P35),1),"")} -> 0 | W35: {=IFERROR(INDEX(_xlfn._xlws.FILTER($I$7:$I$1000-$J$7:$J$1000,$G$7:$G$1000=P35),2),"")} -> 0 | X35: {=IFERROR(INDEX(_xlfn._xlws.FILTER($J$7:$J$1000-$I$7:$I$1000,$L$7:$L$1000=P35),1),"")} -> 0 | Y35: {=IFERROR(INDEX(_xlfn._xlws.FILTER($J$7:$J$1000-$I$7:$I$1000,$L$7:$L$1000=P35),2),"")} | Z35: =SUM(V35:Y35) -> 0 | AA35: {=1+SUMPRODUCT(($U$35:$U$38>U35)+(($U$35:$U$38=U35)*($Z$35:$Z$38>Z35)))} -> 1 | AC35: H | AD35: 1 | AE35: {=IFERROR(_xlfn.TEXTJOIN(" - ",TRUE,_xlfn._xlws.FILTER($P$35:$P$38,$AA$35:$AA$38=1)),"")} -> España - Cabo Verde - Arabia Saudita - Uruguay
B36: 19/06/2026 | C36: 16:00 | D36: Escocia vs Marruecos | E36: Estadio Boston | F36: {=_xlfn.XLOOKUP(TRUE,(GRUPOS!$B$40:$B$51=G36)+(GRUPOS!$C$40:$C$51=G36)+(GRUPOS!$D$40:$D$51=G36)+(GRUPOS!$E$40:$E$51=G36)>0,GRUPOS!$A$40:$A$51)} -> C | G36: =LEFT(D36,FIND(" vs ",D36)-1) -> Escocia | L36: =MID(D36,FIND(" vs ",D36)+4,LEN(D36)) -> Marruecos | M36: {=_xlfn.XLOOKUP(TRUE,(GRUPOS!$B$40:$B$51=L36)+(GRUPOS!$C$40:$C$51=L36)+(GRUPOS!$D$40:$D$51=L36)+(GRUPOS!$E$40:$E$51=L36)>0,GRUPOS!$A$40:$A$51)} -> C | O36: H | P36: Cabo Verde | Q36: {=IFERROR(CHOOSE(MATCH(INDEX(_xlfn._xlws.FILTER($H$7:$H$1000,$G$7:$G$1000=P36),1),{"Perdió","Empató","Ganó"},0),0,1,3),"")} | R36: {=IFERROR(CHOOSE(MATCH(INDEX(_xlfn._xlws.FILTER($H$7:$H$1000,$G$7:$G$1000=P36),2),{"Perdió","Empató","Ganó"},0),0,1,3),"")} | S36: {=IFERROR(CHOOSE(MATCH(INDEX(_xlfn._xlws.FILTER($K$7:$K$1000,$L$7:$L$1000=P36),1),{"Perdió","Empató","Ganó"},0),0,1,3),"")} | T36: {=IFERROR(CHOOSE(MATCH(INDEX(_xlfn._xlws.FILTER($K$7:$K$1000,$L$7:$L$1000=P36),2),{"Perdió","Empató","Ganó"},0),0,1,3),"")} | U36: =SUM(Q36:S36) -> 0 | V36: {=IFERROR(INDEX(_xlfn._xlws.FILTER($I$7:$I$1000-$J$7:$J$1000,$G$7:$G$1000=P36),1),"")} -> 0 | W36: {=IFERROR(INDEX(_xlfn._xlws.FILTER($I$7:$I$1000-$J$7:$J$1000,$G$7:$G$1000=P36),2),"")} | X36: {=IFERROR(INDEX(_xlfn._xlws.FILTER($J$7:$J$1000-$I$7:$I$1000,$L$7:$L$1000=P36),1),"")} -> 0 | Y36: {=IFERROR(INDEX(_xlfn._xlws.FILTER($J$7:$J$1000-$I$7:$I$1000,$L$7:$L$1000=P36),2),"")} -> 0 | Z36: =SUM(V36:Y36) -> 0 | AA36: {=1+SUMPRODUCT(($U$35:$U$38>U36)+(($U$35:$U$38=U36)*($Z$35:$Z$38>Z36)))} -> 1 | AC36: H | AD36: 2 | AE36: {=IFERROR(_xlfn.TEXTJOIN(" - ",TRUE,_xlfn._xlws.FILTER($P$35:$P$38,$AA$35:$AA$38=2)),"")}
B37: 19/06/2026 | C37: 18:30 | D37: Brasil vs Haití | E37: Estadio Filadelfia | F37: {=_xlfn.XLOOKUP(TRUE,(GRUPOS!$B$40:$B$51=G37)+(GRUPOS!$C$40:$C$51=G37)+(GRUPOS!$D$40:$D$51=G37)+(GRUPOS!$E$40:$E$51=G37)>0,GRUPOS!$A$40:$A$51)} -> C | G37: =LEFT(D37,FIND(" vs ",D37)-1) -> Brasil | L37: =MID(D37,FIND(" vs ",D37)+4,LEN(D37)) -> Haití | M37: {=_xlfn.XLOOKUP(TRUE,(GRUPOS!$B$40:$B$51=L37)+(GRUPOS!$C$40:$C$51=L37)+(GRUPOS!$D$40:$D$51=L37)+(GRUPOS!$E$40:$E$51=L37)>0,GRUPOS!$A$40:$A$51)} -> C | O37: H | P37: Arabia Saudita | Q37: {=IFERROR(CHOOSE(MATCH(INDEX(_xlfn._xlws.FILTER($H$7:$H$1000,$G$7:$G$1000=P37),1),{"Perdió","Empató","Ganó"},0),0,1,3),"")} | R37: {=IFERROR(CHOOSE(MATCH(INDEX(_xlfn._xlws.FILTER($H$7:$H$1000,$G$7:$G$1000=P37),2),{"Perdió","Empató","Ganó"},0),0,1,3),"")} | S37: {=IFERROR(CHOOSE(MATCH(INDEX(_xlfn._xlws.FILTER($K$7:$K$1000,$L$7:$L$1000=P37),1),{"Perdió","Empató","Ganó"},0),0,1,3),"")} | T37: {=IFERROR(CHOOSE(MATCH(INDEX(_xlfn._xlws.FILTER($K$7:$K$1000,$L$7:$L$1000=P37),2),{"Perdió","Empató","Ganó"},0),0,1,3),"")} | U37: =SUM(Q37:S37) -> 0 | V37: {=IFERROR(INDEX(_xlfn._xlws.FILTER($I$7:$I$1000-$J$7:$J$1000,$G$7:$G$1000=P37),1),"")} -> 0 | W37: {=IFERROR(INDEX(_xlfn._xlws.FILTER($I$7:$I$1000-$J$7:$J$1000,$G$7:$G$1000=P37),2),"")} | X37: {=IFERROR(INDEX(_xlfn._xlws.FILTER($J$7:$J$1000-$I$7:$I$1000,$L$7:$L$1000=P37),1),"")} -> 0 | Y37: {=IFERROR(INDEX(_xlfn._xlws.FILTER($J$7:$J$1000-$I$7:$I$1000,$L$7:$L$1000=P37),2),"")} -> 0 | Z37: =SUM(V37:Y37) -> 0 | AA37: {=1+SUMPRODUCT(($U$35:$U$38>U37)+(($U$35:$U$38=U37)*($Z$35:$Z$38>Z37)))} -> 1 | AC37: H | AD37: 3 | AE37: {=IFERROR(_xlfn.TEXTJOIN(" - ",TRUE,_xlfn._xlws.FILTER($P$35:$P$38,$AA$35:$AA$38=3)),"")}
B38: 19/06/2026 | C38: 21:00 | D38: Turquía vs Paraguay | E38: Estadio Bahía de San Francisco | F38: {=_xlfn.XLOOKUP(TRUE,(GRUPOS!$B$40:$B$51=G38)+(GRUPOS!$C$40:$C$51=G38)+(GRUPOS!$D$40:$D$51=G38)+(GRUPOS!$E$40:$E$51=G38)>0,GRUPOS!$A$40:$A$51)} -> D | G38: =LEFT(D38,FIND(" vs ",D38)-1) -> Turquía | L38: =MID(D38,FIND(" vs ",D38)+4,LEN(D38)) -> Paraguay | M38: {=_xlfn.XLOOKUP(TRUE,(GRUPOS!$B$40:$B$51=L38)+(GRUPOS!$C$40:$C$51=L38)+(GRUPOS!$D$40:$D$51=L38)+(GRUPOS!$E$40:$E$51=L38)>0,GRUPOS!$A$40:$A$51)} -> D | O38: H | P38: Uruguay | Q38: {=IFERROR(CHOOSE(MATCH(INDEX(_xlfn._xlws.FILTER($H$7:$H$1000,$G$7:$G$1000=P38),1),{"Perdió","Empató","Ganó"},0),0,1,3),"")} | R38: {=IFERROR(CHOOSE(MATCH(INDEX(_xlfn._xlws.FILTER($H$7:$H$1000,$G$7:$G$1000=P38),2),{"Perdió","Empató","Ganó"},0),0,1,3),"")} | S38: {=IFERROR(CHOOSE(MATCH(INDEX(_xlfn._xlws.FILTER($K$7:$K$1000,$L$7:$L$1000=P38),1),{"Perdió","Empató","Ganó"},0),0,1,3),"")} | T38: {=IFERROR(CHOOSE(MATCH(INDEX(_xlfn._xlws.FILTER($K$7:$K$1000,$L$7:$L$1000=P38),2),{"Perdió","Empató","Ganó"},0),0,1,3),"")} | U38: =SUM(Q38:S38) -> 0 | V38: {=IFERROR(INDEX(_xlfn._xlws.FILTER($I$7:$I$1000-$J$7:$J$1000,$G$7:$G$1000=P38),1),"")} -> 0 | W38: {=IFERROR(INDEX(_xlfn._xlws.FILTER($I$7:$I$1000-$J$7:$J$1000,$G$7:$G$1000=P38),2),"")} -> 0 | X38: {=IFERROR(INDEX(_xlfn._xlws.FILTER($J$7:$J$1000-$I$7:$I$1000,$L$7:$L$1000=P38),1),"")} -> 0 | Y38: {=IFERROR(INDEX(_xlfn._xlws.FILTER($J$7:$J$1000-$I$7:$I$1000,$L$7:$L$1000=P38),2),"")} | Z38: =SUM(V38:Y38) -> 0 | AA38: {=1+SUMPRODUCT(($U$35:$U$38>U38)+(($U$35:$U$38=U38)*($Z$35:$Z$38>Z38)))} -> 1 | AC38: H | AD38: 4 | AE38: {=IFERROR(_xlfn.TEXTJOIN(" - ",TRUE,_xlfn._xlws.FILTER($P$35:$P$38,$AA$35:$AA$38=4)),"")}
B39: 20/06/2026 | C39: 11:00 | D39: Países Bajos vs Suecia | E39: Estadio Houston | F39: {=_xlfn.XLOOKUP(TRUE,(GRUPOS!$B$40:$B$51=G39)+(GRUPOS!$C$40:$C$51=G39)+(GRUPOS!$D$40:$D$51=G39)+(GRUPOS!$E$40:$E$51=G39)>0,GRUPOS!$A$40:$A$51)} -> F | G39: =LEFT(D39,FIND(" vs ",D39)-1) -> Países Bajos | L39: =MID(D39,FIND(" vs ",D39)+4,LEN(D39)) -> Suecia | M39: {=_xlfn.XLOOKUP(TRUE,(GRUPOS!$B$40:$B$51=L39)+(GRUPOS!$C$40:$C$51=L39)+(GRUPOS!$D$40:$D$51=L39)+(GRUPOS!$E$40:$E$51=L39)>0,GRUPOS!$A$40:$A$51)} -> F | O39: I | P39: Francia | Q39: {=IFERROR(CHOOSE(MATCH(INDEX(_xlfn._xlws.FILTER($H$7:$H$1000,$G$7:$G$1000=P39),1),{"Perdió","Empató","Ganó"},0),0,1,3),"")} | R39: {=IFERROR(CHOOSE(MATCH(INDEX(_xlfn._xlws.FILTER($H$7:$H$1000,$G$7:$G$1000=P39),2),{"Perdió","Empató","Ganó"},0),0,1,3),"")} | S39: {=IFERROR(CHOOSE(MATCH(INDEX(_xlfn._xlws.FILTER($K$7:$K$1000,$L$7:$L$1000=P39),1),{"Perdió","Empató","Ganó"},0),0,1,3),"")} | T39: {=IFERROR(CHOOSE(MATCH(INDEX(_xlfn._xlws.FILTER($K$7:$K$1000,$L$7:$L$1000=P39),2),{"Perdió","Empató","Ganó"},0),0,1,3),"")} | U39: =SUM(Q39:S39) -> 0 | V39: {=IFERROR(INDEX(_xlfn._xlws.FILTER($I$7:$I$1000-$J$7:$J$1000,$G$7:$G$1000=P39),1),"")} -> 0 | W39: {=IFERROR(INDEX(_xlfn._xlws.FILTER($I$7:$I$1000-$J$7:$J$1000,$G$7:$G$1000=P39),2),"")} -> 0 | X39: {=IFERROR(INDEX(_xlfn._xlws.FILTER($J$7:$J$1000-$I$7:$I$1000,$L$7:$L$1000=P39),1),"")} -> 0 | Y39: {=IFERROR(INDEX(_xlfn._xlws.FILTER($J$7:$J$1000-$I$7:$I$1000,$L$7:$L$1000=P39),2),"")} | Z39: =SUM(V39:Y39) -> 0 | AA39: {=1+SUMPRODUCT(($U$39:$U$42>U39)+(($U$39:$U$42=U39)*($Z$39:$Z$42>Z39)))} -> 1 | AC39: I | AD39: 1 | AE39: {=IFERROR(_xlfn.TEXTJOIN(" - ",TRUE,_xlfn._xlws.FILTER($P$39:$P$42,$AA$39:$AA$42=1)),"")} -> Francia - Senegal - Irak - Noruega
B40: 20/06/2026 | C40: 14:00 | D40: Alemania vs Costa de Marfil | E40: Estadio Toronto | F40: {=_xlfn.XLOOKUP(TRUE,(GRUPOS!$B$40:$B$51=G40)+(GRUPOS!$C$40:$C$51=G40)+(GRUPOS!$D$40:$D$51=G40)+(GRUPOS!$E$40:$E$51=G40)>0,GRUPOS!$A$40:$A$51)} -> E | G40: =LEFT(D40,FIND(" vs ",D40)-1) -> Alemania | L40: =MID(D40,FIND(" vs ",D40)+4,LEN(D40)) -> Costa de Marfil | M40: {=_xlfn.XLOOKUP(TRUE,(GRUPOS!$B$40:$B$51=L40)+(GRUPOS!$C$40:$C$51=L40)+(GRUPOS!$D$40:$D$51=L40)+(GRUPOS!$E$40:$E$51=L40)>0,GRUPOS!$A$40:$A$51)} -> E | O40: I | P40: Senegal | Q40: {=IFERROR(CHOOSE(MATCH(INDEX(_xlfn._xlws.FILTER($H$7:$H$1000,$G$7:$G$1000=P40),1),{"Perdió","Empató","Ganó"},0),0,1,3),"")} | R40: {=IFERROR(CHOOSE(MATCH(INDEX(_xlfn._xlws.FILTER($H$7:$H$1000,$G$7:$G$1000=P40),2),{"Perdió","Empató","Ganó"},0),0,1,3),"")} | S40: {=IFERROR(CHOOSE(MATCH(INDEX(_xlfn._xlws.FILTER($K$7:$K$1000,$L$7:$L$1000=P40),1),{"Perdió","Empató","Ganó"},0),0,1,3),"")} | T40: {=IFERROR(CHOOSE(MATCH(INDEX(_xlfn._xlws.FILTER($K$7:$K$1000,$L$7:$L$1000=P40),2),{"Perdió","Empató","Ganó"},0),0,1,3),"")} | U40: =SUM(Q40:S40) -> 0 | V40: {=IFERROR(INDEX(_xlfn._xlws.FILTER($I$7:$I$1000-$J$7:$J$1000,$G$7:$G$1000=P40),1),"")} -> 0 | W40: {=IFERROR(INDEX(_xlfn._xlws.FILTER($I$7:$I$1000-$J$7:$J$1000,$G$7:$G$1000=P40),2),"")} | X40: {=IFERROR(INDEX(_xlfn._xlws.FILTER($J$7:$J$1000-$I$7:$I$1000,$L$7:$L$1000=P40),1),"")} -> 0 | Y40: {=IFERROR(INDEX(_xlfn._xlws.FILTER($J$7:$J$1000-$I$7:$I$1000,$L$7:$L$1000=P40),2),"")} -> 0 | Z40: =SUM(V40:Y40) -> 0 | AA40: {=1+SUMPRODUCT(($U$39:$U$42>U40)+(($U$39:$U$42=U40)*($Z$39:$Z$42>Z40)))} -> 1 | AC40: I | AD40: 2 | AE40: {=IFERROR(_xlfn.TEXTJOIN(" - ",TRUE,_xlfn._xlws.FILTER($P$39:$P$42,$AA$39:$AA$42=2)),"")}
